Workbook
Name LISTA_OBJETIVOS: [13]apoio!$G$2:$G$13

Sheet CAPA
B2: PLANO DE MÍDIA
B4: CLIENTE | C4: : | D4: MINISTÉRIO DA EDUCAÇÃO
B6: CAMPANHA | C6: : | D6: FIES 2026
B8: PERÍODO | C8: : | D8: JULHO DE 2026
B10: AÇÃO MIDIAWEB | C10: :
B12: TIPO DE CAMPANHA | C12: : | D12: UTILIDADE PÚBLICA
B14: VERSÃO | C14: : | D14: V1
B16: TOTAL NEGOCIADO (100%) | C16: : | D16: =RESUMO!G65 -> 3972547.1
B18: TOTAL DESEMBOLSO (95%) | C18: : | D18: =RESUMO!H65 -> 3819999.8
B20: TOTAL PRODUÇÃO | C20: : | D20: =CRONO!AK18 -> 180000
B22: TOTAL MÍDIA (94,5%) + PRODUÇÃO | C22: : | D22: =D20+D18 -> 3999999.8
B24: DATA | C24: : | D24: 15/07/2026

Sheet CRONO
B2: CRONOGRAMA DE VEICULAÇÃO
B3: =RESUMO!C5 -> MINISTÉRIO DA EDUCAÇÃO
B4: =RESUMO!C6 -> FIES 2026
B6: MEIO | C6: MERCADO | D6: FORMATO | E6: PERÍODO DETALHADO DE VEICULAÇÃO | F6: JUNHO 2026 - 06/2026 | Q6: JULHO | AJ6: VALOR TOTAL NEGOCIADO 100% | AK6: VALOR DESEMBOLSO 95% | AM6: PART. MEIO %
F7: 1 | G7: =F7+1 -> 2 | H7: =G7+1 -> 3 | I7: =H7+1 -> 4 | J7: =I7+1 -> 5 | K7: =J7+1 -> 6 | L7: =K7+1 -> 7 | M7: =L7+1 -> 8 | N7: =M7+1 -> 9 | ... P7: =O7+1 -> 11 | Q7: 10 | R7: =Q7+1 -> 11 | S7: =R7+1 -> 12 | T7: =S7+1 -> 13 | U7: =T7+1 -> 14 | V7: =U7+1 -> 15 | W7: =V7+1 -> 16 | X7: =W7+1 -> 17 | Y7: =X7+1 -> 18 | ... AI7: =AH7+1 -> 28
F8: S | G8: T | H8: Q | I8: Q | J8: S | K8: S | L8: D | M8: S | N8: T | O8: Q | P8: Q | Q8: S | R8: S | S8: D | T8: S | U8: T | V8: Q | W8: Q | X8: S | Y8: S | Z8: D | AA8: S | AB8: T | AC8: Q | AD8: Q | AE8: S | AF8: S | AG8: D | AH8: S | AI8: T
B10: MÍDIA EXTERIOR | AJ10: =SUM(AJ11:AJ11) -> 2138848.9 | AK10: =SUM(AK11:AK11) -> 2031906.5 | AM10: =AK10/$AK$16 -> 0.53191272
B11: DOOH | C11: DF, SP, BA, RJ, CE, PR, PE, AM, MG, GO, PA, PI, MA | D11: 10" - 15" | E11: DE 16/07 A17/07 | AJ11: ='DOOH - METRÔ'!G33+'DOOH - MUB'!G28+'DOOH - ESTABELECIMENTOS'!F37+'DOOH - PAINEL'!F169+'DOOH - TERMINAL RODOVIÁRIO'!G36 -> 2138848.9 | AK11: =AJ11*0.95 -> 2031906.5 | AM11: =AK11/$AK$20 -> 0.50797665
B13: INTERNET | AJ13: =SUM(AJ14:AJ14) -> 1833698.2 | AK13: =SUM(AK14:AK14) -> 1788093.3 | AM13: =AK13/$AK$16 -> 0.46808728
B14: INTERNET | C14: NACIONAL | D14: DIVERSOS | E14: DE 16/07 A17/07 | AJ14: =INTERNET!AH32 -> 1833698.2 | AK14: =INTERNET!AJ32 -> 1788093.3 | AM14: =AK14/$AK$20 -> 0.44702335
B16: TOTAL MÍDIA | AJ16: =AJ10+AJ13 -> 3972547.1 | AK16: =AK10+AK13 -> 3819999.8 | AM16: =AK16/AK20 -> 0.955
B18: TOTAL PREVISTO PARA PRODUÇÃO DE MÍDIA | AK18: 180000 | AM18: =AK18/AK20 -> 0.045000003
B20: TOTAL GERAL | AK20: =AK18+AK16 -> 3999999.8 | AM20: =AM16+AM18 -> 1

Sheet RESUMO
C1: #EXTERNO.CONFIDENCIAL
C3: RESUMO DE VERBA
C5: =CAPA!D4 -> MINISTÉRIO DA EDUCAÇÃO
C6: =CAPA!D6 -> FIES 2026
C7: =CAPA!D8 -> JULHO DE 2026
C9: MEIO | D9: TIPO | E9: PRAÇA | G9: VALOR 100% | H9: VALOR TOTAL 95% | I9: % MEIO | J9: % CAMPANHA | L9: REPRESENTANTE
C12: MIDIA EXTERIOR DIGITAL
C13: URBAN + | D13: METRÔ | E13: DF | G13: ='DOOH - METRÔ'!G28 -> 37273.6 | H13: =G13*0.95 -> 35409.92 | I13: =H13/$H$47 -> 0.017426944 | J13: =H13/$H$65 -> 0.0092696132 | L13: MIDIA MAIS
C14: MOBTV | D14: METRÔ | E14: DF | G14: ='DOOH - METRÔ'!G29 -> 44626.4 | H14: =G14*0.95 -> 42395.08 | I14: =H14/$H$47 -> 0.020864681 | J14: =H14/$H$65 -> 0.011098189 | L14: DS MIDIA
C15: MEDIA MEGAS | D15: METRÔ | E15: SP | G15: ='DOOH - METRÔ'!G30 -> 209000 | H15: =G15*0.95 -> 198550 | I15: =H15/$H$47 -> 0.097716112 | J15: =H15/$H$65 -> 0.051976443 | L15: MEDIA MEGAS
C16: ELETROMÍDIA - TV MINUTO | D16: METRÔ | E16: SP | G16: ='DOOH - METRÔ'!G31 -> 56262.246 | H16: =G16*0.95 -> 53449.134 | I16: =H16/$H$47 -> 0.026304918 | J16: =H16/$H$65 -> 0.013991921 | L16: STREET
C17: ELETROMIDIA | D17: METRÔ | E17: RJ | G17: ='DOOH - METRÔ'!G32 -> 0 | H17: =G17*0.95 -> 0 | I17: =H17/$H$47 -> 0 | J17: =H17/$H$65 -> 0 | L17: STREET
C18: VISUPLAC | D18: MUB | E18: DF | G18: ='DOOH - MUB'!G24 -> 67961.143 | H18: ='DOOH - MUB'!H24 -> 64563.086 | I18: =H18/$H$47 -> 0.031774635 | J18: =H18/$H$65 -> 0.016901332 | L18: MOSAICO
C19: PLUREX | D19: MUB | E19: RJ | G19: ='DOOH - MUB'!G25 -> 24624 | H19: ='DOOH - MUB'!H25 -> 23392.8 | I19: =H19/$H$47 -> 0.011512735 | J19: =H19/$H$65 -> 0.00612377 | L19: BO GROUP
C20: DESTAKE | D20: MUB | E20: MG | G20: ='DOOH - MUB'!G26 -> 129846 | H20: ='DOOH - MUB'!H26 -> 123353.7 | I20: =H20/$H$47 -> 0.060708355 | J20: =H20/$H$65 -> 0.032291547 | L20: MIDIA MAIS
C21: ELETROMIDIA | D21: MUB | E21: SP | G21: ='DOOH - MUB'!G27 -> 128280.71 | H21: ='DOOH - MUB'!H27 -> 121866.68 | I21: =H21/$H$47 -> 0.059976519 | J21: =H21/$H$65 -> 0.031902274 | L21: STREET
C22: INSIGHT MIDIA | D22: ESTABELECIMENTOS | E22: PE, CE, DF, SP, BA, PR | G22: ='DOOH - ESTABELECIMENTOS'!F35 -> 243456 | H22: ='DOOH - ESTABELECIMENTOS'!G35 -> 231283.2 | I22: =H22/$H$47 -> 0.11382571 | J22: =H22/$H$65 -> 0.060545344 | L22: INSIGHT
C23: BEEP MIDIA | D23: ESTABELECIMENTOS | E23: PA, RJ, MA | G23: ='DOOH - ESTABELECIMENTOS'!F36 -> 117924 | H23: ='DOOH - ESTABELECIMENTOS'!G36 -> 112027.8 | I23: =H23/$H$47 -> 0.055134329 | J23: =H23/$H$65 -> 0.029326651 | L23: BEEP MIDIA
C24: WE SUPER OOH | D24: PAINEL DE LED | E24: PE, CE, GO | G24: ='DOOH - PAINEL'!F150 -> 54847.605 | H24: ='DOOH - PAINEL'!H150 -> 52105.225 | I24: =H24/$H$47 -> 0.025643515 | J24: =H24/$H$65 -> 0.013640112 | L24: MOSAICO
C25: MLA MIDIA | D25: PAINEL DE LED | E25: PE, DF | G25: ='DOOH - PAINEL'!F151 -> 40759.2 | H25: ='DOOH - PAINEL'!H151 -> 38721.24 | I25: =H25/$H$47 -> 0.019056605 | J25: =H25/$H$65 -> 0.010136451 | L25: MLA MIDIA
C26: LED MAIS | D26: PAINEL DE LED | E26: PR, BA, CE, DF, GO | G26: ='DOOH - PAINEL'!F152 -> 66960 | H26: ='DOOH - PAINEL'!H152 -> 63612 | I26: =H26/$H$47 -> 0.031306559 | J26: =H26/$H$65 -> 0.016652357 | L26: G2
C27: PLAN PAINÉIS | D27: PAINEL DE LED | E27: PR, CE, AM | G27: ='DOOH - PAINEL'!F153 -> 22403.571 | H27: ='DOOH - PAINEL'!H153 -> 21283.393 | I27: =H27/$H$47 -> 0.010474593 | J27: =H27/$H$65 -> 0.0055715692 | L27: PLAN PAINEIS
C28: 55 MÍDIA | D28: PAINEL DE LED | E28: CE | G28: ='DOOH - PAINEL'!F154 -> 115347.9 | H28: ='DOOH - PAINEL'!H154 -> 109580.5 | I28: =H28/$H$47 -> 0.053929896 | J28: =H28/$H$65 -> 0.028685998 | L28: MIDIA MAIS
C29: NORDESTE MIDIA EXTERIOR DIGITAL | D29: PAINEL DE LED | E29: CE | G29: ='DOOH - PAINEL'!F155 -> 22400 | H29: ='DOOH - PAINEL'!H155 -> 21280 | I29: =H29/$H$47 -> 0.010472923 | J29: =H29/$H$65 -> 0.005570681
C30: URB | D30: PAINEL DE LED | E30: AM, PI, PA | G30: ='DOOH - PAINEL'!F156 -> 66047 | H30: ='DOOH - PAINEL'!H156 -> 62744.65 | I30: =H30/$H$47 -> 0.030879694 | J30: =H30/$H$65 -> 0.016425302
C31: ALTERNAMIDIA | D31: PAINEL DE LED | E31: AM, MG, GO | G31: ='DOOH - PAINEL'!F157 -> 56729.991 | H31: ='DOOH - PAINEL'!H157 -> 53893.491 | I31: =H31/$H$47 -> 0.026523608 | J31: =H31/$H$65 -> 0.014108245
C32: DMIDIA | D32: PAINEL DE LED | E32: MG | G32: ='DOOH - PAINEL'!F158 -> 34644.998 | H32: ='DOOH - PAINEL'!H158 -> 32912.748 | I32: =H32/$H$47 -> 0.016197964 | J32: =H32/$H$65 -> 0.0086159032
C33: DOORS | D33: PAINEL DE LED | E33: MG, GO | G33: ='DOOH - PAINEL'!F159 -> 63104 | H33: ='DOOH - PAINEL'!H159 -> 59948.8 | I33: =H33/$H$47 -> 0.02950372 | J33: =H33/$H$65 -> 0.015693404
C34: TRAFFIC LED | D34: PAINEL DE LED | E34: DF | G34: ='DOOH - PAINEL'!F160 -> 11995.62 | H34: ='DOOH - PAINEL'!H160 -> 11395.839 | I34: =H34/$H$47 -> 0.0056084466 | J34: =H34/$H$65 -> 0.0029832041
C35: LEDME | D35: PAINEL DE LED | E35: DF | G35: ='DOOH - PAINEL'!F161 -> 50656.32 | H35: ='DOOH - PAINEL'!H161 -> 48123.504 | I35: =H35/$H$47 -> 0.023683917 | J35: =H35/$H$65 -> 0.012597777
C36: UNIVERSO BR DOOH | D36: PAINEL DE LED | E36: DF, SP | G36: ='DOOH - PAINEL'!F162 -> 22205.714 | H36: ='DOOH - PAINEL'!H162 -> 21095.429 | I36: =H36/$H$47 -> 0.010382086 | J36: =H36/$H$65 -> 0.0055223639
C37: ANUNCIART | D37: PAINEL DE LED | E37: DF | G37: ='DOOH - PAINEL'!F163 -> 26058.24 | H37: ='DOOH - PAINEL'!H163 -> 24755.328 | I37: =H37/$H$47 -> 0.012183301 | J37: =H37/$H$65 -> 0.0064804528
C38: EAGLE PUBLICITY | D38: PAINEL DE LED | E38: DF | G38: ='DOOH - PAINEL'!F164 -> 81884.4 | H38: ='DOOH - PAINEL'!H164 -> 77790.18 | I38: =H38/$H$47 -> 0.038284331 | J38: =H38/$H$65 -> 0.020363923
C39: AGENCIA MAJESTIC DOOH | D39: PAINEL DE LED | E39: DF | G39: ='DOOH - PAINEL'!F165 -> 63000 | H39: ='DOOH - PAINEL'!H165 -> 59850 | I39: =H39/$H$47 -> 0.029455096 | J39: =H39/$H$65 -> 0.01566754
C40: ALTO IMPACTO | D40: PAINEL DE LED | E40: RJ | G40: ='DOOH - PAINEL'!F166 -> 31146.667 | H40: ='DOOH - PAINEL'!H166 -> 29589.333 | I40: =H40/$H$47 -> 0.01456235 | J40: =H40/$H$65 -> 0.0077458993
... C42: INTELICOM | D42: PAINEL DE LED | E42: PE | G42: ='DOOH - PAINEL'!F168 -> 55478.6 | H42: ='DOOH - PAINEL'!H168 -> 52704.67 | I42: =H42/$H$47 -> 0.025938531 | J42: =H42/$H$65 -> 0.013797035
C43: MOBILAPA | D43: TERM. RODOVIÁRIO | E43: BA | G43: ='DOOH - TERMINAL RODOVIÁRIO'!G32 -> 29281.714 | H43: ='DOOH - TERMINAL RODOVIÁRIO'!H32 -> 27817.629 | I43: =H43/$H$47 -> 0.013690408 | J43: =H43/$H$65 -> 0.0072821022 | L43: PLAN PAINÉIS
C44: ALL 7 MIDIA | D44: TERM. RODOVIÁRIO | E44: BA | G44: ='DOOH - TERMINAL RODOVIÁRIO'!G33 -> 19511.28 | H44: ='DOOH - TERMINAL RODOVIÁRIO'!H33 -> 18535.716 | I44: =H44/$H$47 -> 0.0091223273 | J44: =H44/$H$65 -> 0.004852282 | L44: ALTERNAMIDIA
C45: MIDI | D45: TERM. RODOVIÁRIO | E45: BA | G45: ='DOOH - TERMINAL RODOVIÁRIO'!G34 -> 70761.6 | H45: ='DOOH - TERMINAL RODOVIÁRIO'!H34 -> 67223.52 | I45: =H45/$H$47 -> 0.033083964 | J45: =H45/$H$65 -> 0.017597781 | L45: G2
C46: ONBUS | D46: TERM. RODOVIÁRIO | E46: RJ | G46: ='DOOH - TERMINAL RODOVIÁRIO'!G35 -> 16070.4 | H46: ='DOOH - TERMINAL RODOVIÁRIO'!H35 -> 15266.88 | I46: =H46/$H$47 -> 0.0075135742 | J46: =H46/$H$65 -> 0.0039965657 | L46: MIDIALAND
...

Sheet RESUMO -ME
B2: RESUMO DE VERBA - MÍDIA EXTERIOR
B4: =CAPA!D4 -> MINISTÉRIO DA EDUCAÇÃO
B5: =CAPA!D6 -> FIES 2026
B6: =CAPA!D8 -> JULHO DE 2026
B8: PRAÇA / MEIO | D8: DOOH | J8: TOTAL POR PRAÇA | K8: VALOR DESEMBOLSO 95% | L8: POPULAÇÃO | M8: SHARE POPULAÇÃO | N8: PARTICIPAÇÃO
D9: METRÔ | E9: PAINEL | F9: TERM. ROD. | G9: MUB | H9: ESTABELECIMENTOS
B10: REGIÃO SUDESTE
B11: #VALUE! | C11: RJ | D11: =SUMIF('DOOH - METRÔ'!$C$8:$C$22,C11,'DOOH - METRÔ'!$W$8:$W$22) -> 0 | E11: =SUMIF('DOOH - PAINEL'!$C:$C,'RESUMO -ME'!C11,'DOOH - PAINEL'!$X:$X) -> 89446.667 | F11: =SUMIF('DOOH - TERMINAL RODOVIÁRIO'!$C$11:$C$26,'RESUMO -ME'!C11,'DOOH - TERMINAL RODOVIÁRIO'!$X$11:$X$26) -> 16070.4 | G11: =SUMIF('DOOH - MUB'!$C$11:$C$17,'RESUMO -ME'!C11,'DOOH - MUB'!$X$11:$X$17) -> 24624 | H11: =SUMIF('DOOH - ESTABELECIMENTOS'!$C$11:$C$28,'RESUMO -ME'!C11,'DOOH - ESTABELECIMENTOS'!$W$11:$W$28) -> 47988 | I11: {=_FV(B11,"População")} -> 6730729 | J11: =SUM(D11:H11) -> 178129.07 | K11: =J11*0.95 -> 169222.61 | L11: {=_FV(B11,"População")} -> 6730729 | M11: =L11/$L$28 -> 0.16907331 | N11: =K11/$K$28 -> 0.083282678
B12: #VALUE! | C12: SP | D12: =SUMIF('DOOH - METRÔ'!$C$8:$C$22,C12,'DOOH - METRÔ'!$W$8:$W$22) -> 265262.25 | E12: =SUMIF('DOOH - PAINEL'!$C:$C,'RESUMO -ME'!C12,'DOOH - PAINEL'!$X:$X) -> 15314.286 | F12: =SUMIF('DOOH - TERMINAL RODOVIÁRIO'!$C$11:$C$26,'RESUMO -ME'!C12,'DOOH - TERMINAL RODOVIÁRIO'!$X$11:$X$26) -> 0 | G12: =SUMIF('DOOH - MUB'!$C$11:$C$17,'RESUMO -ME'!C12,'DOOH - MUB'!$X$11:$X$17) -> 128280.71 | H12: =SUMIF('DOOH - ESTABELECIMENTOS'!$C$11:$C$28,'RESUMO -ME'!C12,'DOOH - ESTABELECIMENTOS'!$W$11:$W$28) -> 76416 | J12: =SUM(D12:H12) -> 485273.25 | K12: =J12*0.95 -> 461009.58 | L12: {=_FV(B12,"População")} -> 11904961 | M12: =L12/$L$28 -> 0.29904802 | N12: =K12/$K$28 -> 0.22688524
B13: #VALUE! | C13: MG | D13: =SUMIF('DOOH - METRÔ'!$C$8:$C$22,C13,'DOOH - METRÔ'!$W$8:$W$22) -> 0 | E13: =SUMIF('DOOH - PAINEL'!$C:$C,'RESUMO -ME'!C13,'DOOH - PAINEL'!$X:$X) -> 85051.849 | F13: =SUMIF('DOOH - TERMINAL RODOVIÁRIO'!$C$11:$C$26,'RESUMO -ME'!C13,'DOOH - TERMINAL RODOVIÁRIO'!$X$11:$X$26) -> 0 | G13: =SUMIF('DOOH - MUB'!$C$11:$C$17,'RESUMO -ME'!C13,'DOOH - MUB'!$X$11:$X$17) -> 129846 | H13: =SUMIF('DOOH - ESTABELECIMENTOS'!$C$11:$C$28,'RESUMO -ME'!C13,'DOOH - ESTABELECIMENTOS'!$W$11:$W$28) -> 0 | J13: =SUM(D13:H13) -> 214897.85 | K13: =J13*0.95 -> 204152.96 | L13: {=_FV(B13,"População")} -> 2415872 | M13: =L13/$L$28 -> 0.060685772 | N13: =K13/$K$28 -> 0.1004736
B14: REGIÃO CENTRO OESTE | E14: =SUMIF('DOOH - PAINEL'!$C:$C,'RESUMO -ME'!C14,'DOOH - PAINEL'!$X:$X) -> 0
B15: #VALUE! | C15: GO | D15: =SUMIF('DOOH - METRÔ'!$C$8:$C$22,C15,'DOOH - METRÔ'!$W$8:$W$22) -> 0 | E15: =SUMIF('DOOH - PAINEL'!$C:$C,'RESUMO -ME'!C15,'DOOH - PAINEL'!$X:$X) -> 62678.821 | F15: =SUMIF('DOOH - TERMINAL RODOVIÁRIO'!$C$11:$C$26,'RESUMO -ME'!C15,'DOOH - TERMINAL RODOVIÁRIO'!$X$11:$X$26) -> 0 | G15: =SUMIF('DOOH - MUB'!$C$11:$C$17,'RESUMO -ME'!C15,'DOOH - MUB'!$X$11:$X$17) -> 0 | H15: =SUMIF('DOOH - ESTABELECIMENTOS'!$C$11:$C$28,'RESUMO -ME'!C15,'DOOH - ESTABELECIMENTOS'!$W$11:$W$28) -> 0 | J15: =SUM(D15:H15) -> 62678.821 | K15: =J15*0.95 -> 59544.88 | L15: {=_FV(B15,"População")} -> 1503256 | M15: =L15/$L$28 -> 0.03776121 | N15: =K15/$K$28 -> 0.029304931
B16: #VALUE! | C16: DF | D16: =SUMIF('DOOH - METRÔ'!$C$8:$C$22,C16,'DOOH - METRÔ'!$W$8:$W$22) -> 81900 | E16: =SUMIF('DOOH - PAINEL'!$C:$C,'RESUMO -ME'!C16,'DOOH - PAINEL'!$X:$X) -> 264278.41 | F16: =SUMIF('DOOH - TERMINAL RODOVIÁRIO'!$C$11:$C$26,'RESUMO -ME'!C16,'DOOH - TERMINAL RODOVIÁRIO'!$X$11:$X$26) -> 0 | G16: =SUMIF('DOOH - MUB'!$C$11:$C$17,'RESUMO -ME'!C16,'DOOH - MUB'!$X$11:$X$17) -> 67961.143 | H16: =SUMIF('DOOH - ESTABELECIMENTOS'!$C$11:$C$28,'RESUMO -ME'!C16,'DOOH - ESTABELECIMENTOS'!$W$11:$W$28) -> 57600 | J16: =SUM(D16:H16) -> 471739.55 | K16: =J16*0.95 -> 448152.57 | L16: {=_FV(B16,"População")} -> 2996899 | M16: =L16/$L$28 -> 0.075280946 | N16: =K16/$K$28 -> 0.22055768
B17: REGIÃO NORTE | E17: =SUMIF('DOOH - PAINEL'!$C:$C,'RESUMO -ME'!C17,'DOOH - PAINEL'!$X:$X) -> 0
B18: #VALUE! | C18: PA | D18: =SUMIF('DOOH - METRÔ'!$C$8:$C$22,C18,'DOOH - METRÔ'!$W$8:$W$22) -> 0 | E18: =SUMIF('DOOH - PAINEL'!$C:$C,'RESUMO -ME'!C18,'DOOH - PAINEL'!$X:$X) -> 17617.6 | F18: =SUMIF('DOOH - TERMINAL RODOVIÁRIO'!$C$11:$C$26,'RESUMO -ME'!C18,'DOOH - TERMINAL RODOVIÁRIO'!$X$11:$X$26) -> 0 | G18: =SUMIF('DOOH - MUB'!$C$11:$C$17,'RESUMO -ME'!C18,'DOOH - MUB'!$X$11:$X$17) -> 0 | H18: =SUMIF('DOOH - ESTABELECIMENTOS'!$C$11:$C$28,'RESUMO -ME'!C18,'DOOH - ESTABELECIMENTOS'!$W$11:$W$28) -> 40548 | J18: =SUM(D18:H18) -> 58165.6 | K18: =J18*0.95 -> 55257.32 | L18: {=_FV(B18,"População")} -> 1397315 | M18: =L18/$L$28 -> 0.035100013 | N18: =K18/$K$28 -> 0.027194815
B19: #VALUE! | C19: AM | D19: =SUMIF('DOOH - METRÔ'!$C$8:$C$22,C19,'DOOH - METRÔ'!$W$8:$W$22) -> 0 | E19: =SUMIF('DOOH - PAINEL'!$C:$C,'RESUMO -ME'!C19,'DOOH - PAINEL'!$X:$X) -> 46990.505 | F19: =SUMIF('DOOH - TERMINAL RODOVIÁRIO'!$C$11:$C$26,'RESUMO -ME'!C19,'DOOH - TERMINAL RODOVIÁRIO'!$X$11:$X$26) -> 0 | G19: =SUMIF('DOOH - MUB'!$C$11:$C$17,'RESUMO -ME'!C19,'DOOH - MUB'!$X$11:$X$17) -> 0 | H19: =SUMIF('DOOH - ESTABELECIMENTOS'!$C$11:$C$28,'RESUMO -ME'!C19,'DOOH - ESTABELECIMENTOS'!$W$11:$W$28) -> 0 | J19: =SUM(D19:H19) -> 46990.505 | K19: =J19*0.95 -> 44640.98 | L19: {=_FV(B19,"População")} -> 2303732 | M19: =L19/$L$28 -> 0.057868858 | N19: =K19/$K$28 -> 0.021969997
B20: REGIÃO SUL | E20: =SUMIF('DOOH - PAINEL'!$C:$C,'RESUMO -ME'!C20,'DOOH - PAINEL'!$X:$X) -> 0
B21: #VALUE! | C21: PR | D21: =SUMIF('DOOH - METRÔ'!$C$8:$C$22,C21,'DOOH - METRÔ'!$W$8:$W$22) -> 0 | E21: =SUMIF('DOOH - PAINEL'!$C:$C,'RESUMO -ME'!C21,'DOOH - PAINEL'!$X:$X) -> 18636.429 | F21: =SUMIF('DOOH - TERMINAL RODOVIÁRIO'!$C$11:$C$26,'RESUMO -ME'!C21,'DOOH - TERMINAL RODOVIÁRIO'!$X$11:$X$26) -> 0 | G21: =SUMIF('DOOH - MUB'!$C$11:$C$17,'RESUMO -ME'!C21,'DOOH - MUB'!$X$11:$X$17) -> 0 | H21: =SUMIF('DOOH - ESTABELECIMENTOS'!$C$11:$C$28,'RESUMO -ME'!C21,'DOOH - ESTABELECIMENTOS'!$W$11:$W$28) -> 26880 | J21: =SUM(D21:H21) -> 45516.429 | K21: =J21*0.95 -> 43240.607 | L21: {=_FV(B21,"População")} -> 1830795 | M21: =L21/$L$28 -> 0.045988864 | N21: =K21/$K$28 -> 0.021280806
B22: REGIÃO NORDESTE | E22: =SUMIF('DOOH - PAINEL'!$C:$C,'RESUMO -ME'!C22,'DOOH - PAINEL'!$X:$X) -> 0 | H22: =SUMIF('DOOH - ESTABELECIMENTOS'!$C$11:$C$28,'RESUMO -ME'!C22,'DOOH - ESTABELECIMENTOS'!$W$11:$W$28) -> 0
B23: #VALUE! | C23: BA | D23: =SUMIF('DOOH - METRÔ'!$C$8:$C$22,C23,'DOOH - METRÔ'!$W$8:$W$22) -> 0 | E23: =SUMIF('DOOH - PAINEL'!$C:$C,'RESUMO -ME'!C23,'DOOH - PAINEL'!$X:$X) -> 16740 | F23: =SUMIF('DOOH - TERMINAL RODOVIÁRIO'!$C$11:$C$26,'RESUMO -ME'!C23,'DOOH - TERMINAL RODOVIÁRIO'!$X$11:$X$26) -> 119554.59 | G23: =SUMIF('DOOH - MUB'!$C$11:$C$17,'RESUMO -ME'!C23,'DOOH - MUB'!$X$11:$X$17) -> 0 | H23: =SUMIF('DOOH - ESTABELECIMENTOS'!$C$11:$C$28,'RESUMO -ME'!C23,'DOOH - ESTABELECIMENTOS'!$W$11:$W$28) -> 24960 | J23: =SUM(D23:H23) -> 161254.59 | K23: =J23*0.95 -> 153191.86 | L23: {=_FV(B23,"População")} -> 2564204 | M23: =L23/$L$28 -> 0.064411815 | N23: =K23/$K$28 -> 0.075393167
B24: #VALUE! | C24: CE | D24: =SUMIF('DOOH - METRÔ'!$C$8:$C$22,C24,'DOOH - METRÔ'!$W$8:$W$22) -> 0 | E24: =SUMIF('DOOH - PAINEL'!$C:$C,'RESUMO -ME'!C24,'DOOH - PAINEL'!$X:$X) -> 231530.38 | F24: =SUMIF('DOOH - TERMINAL RODOVIÁRIO'!$C$11:$C$26,'RESUMO -ME'!C24,'DOOH - TERMINAL RODOVIÁRIO'!$X$11:$X$26) -> 0 | G24: =SUMIF('DOOH - MUB'!$C$11:$C$17,'RESUMO -ME'!C24,'DOOH - MUB'!$X$11:$X$17) -> 0 | H24: =SUMIF('DOOH - ESTABELECIMENTOS'!$C$11:$C$28,'RESUMO -ME'!C24,'DOOH - ESTABELECIMENTOS'!$W$11:$W$28) -> 26880 | J24: =SUM(D24:H24) -> 258410.38 | K24: =J24*0.95 -> 245489.86 | L24: {=_FV(B24,"População")} -> 2578483 | M24: =L24/$L$28 -> 0.064770498 | N24: =K24/$K$28 -> 0.1208175
B25: #VALUE! | C25: MA | D25: =SUMIF('DOOH - METRÔ'!$C$8:$C$22,C25,'DOOH - METRÔ'!$W$8:$W$22) -> 0 | E25: =SUMIF('DOOH - PAINEL'!$C:$C,'RESUMO -ME'!C25,'DOOH - PAINEL'!$X:$X) -> 0 | F25: =SUMIF('DOOH - TERMINAL RODOVIÁRIO'!$C$11:$C$26,'RESUMO -ME'!C25,'DOOH - TERMINAL RODOVIÁRIO'!$X$11:$X$26) -> 0 | G25: =SUMIF('DOOH - MUB'!$C$11:$C$17,'RESUMO -ME'!C25,'DOOH - MUB'!$X$11:$X$17) -> 0 | H25: =SUMIF('DOOH - ESTABELECIMENTOS'!$C$11:$C$28,'RESUMO -ME'!C25,'DOOH - ESTABELECIMENTOS'!$W$11:$W$28) -> 29388 | J25: =SUM(D25:H25) -> 29388 | K25: =J25*0.95 -> 27918.6 | L25: {=_FV(B25,"População")} -> 1089215 | M25: =L25/$L$28 -> 0.02736066 | N25: =K25/$K$28 -> 0.013740101
B26: #VALUE! | C26: pi | D26: =SUMIF('DOOH - METRÔ'!$C$8:$C$22,C26,'DOOH - METRÔ'!$W$8:$W$22) -> 0 | E26: =SUMIF('DOOH - PAINEL'!$C:$C,'RESUMO -ME'!C26,'DOOH - PAINEL'!$X:$X) -> 1355.2 | F26: =SUMIF('DOOH - TERMINAL RODOVIÁRIO'!$C$11:$C$26,'RESUMO -ME'!C26,'DOOH - TERMINAL RODOVIÁRIO'!$X$11:$X$26) -> 0 | G26: =SUMIF('DOOH - MUB'!$C$11:$C$17,'RESUMO -ME'!C26,'DOOH - MUB'!$X$11:$X$17) -> 0 | H26: =SUMIF('DOOH - ESTABELECIMENTOS'!$C$11:$C$28,'RESUMO -ME'!C26,'DOOH - ESTABELECIMENTOS'!$W$11:$W$28) -> 0 | J26: =SUM(D26:H26) -> 1355.2 | K26: =J26*0.95 -> 1287.44 | L26: {=_FV(B26,"População")} -> 905692 | M26: =L26/$L$28 -> 0.022750633 | N26: =K26/$K$28 -> 0.00063361184
B27: #VALUE! | C27: PE | D27: =SUMIF('DOOH - METRÔ'!$C$8:$C$22,C27,'DOOH - METRÔ'!$W$8:$W$22) -> 0 | E27: =SUMIF('DOOH - PAINEL'!$C:$C,'RESUMO -ME'!C27,'DOOH - PAINEL'!$X:$X) -> 94329.686 | F27: =SUMIF('DOOH - TERMINAL RODOVIÁRIO'!$C$11:$C$26,'RESUMO -ME'!C27,'DOOH - TERMINAL RODOVIÁRIO'!$X$11:$X$26) -> 0 | G27: =SUMIF('DOOH - MUB'!$C$11:$C$17,'RESUMO -ME'!C27,'DOOH - MUB'!$X$11:$X$17) -> 0 | H27: =SUMIF('DOOH - ESTABELECIMENTOS'!$C$11:$C$28,'RESUMO -ME'!C27,'DOOH - ESTABELECIMENTOS'!$W$11:$W$28) -> 30720 | J27: =SUM(D27:H27) -> 125049.69 | K27: =J27*0.95 -> 118797.2 | L27: {=_FV(B27,"População")} -> 1588376 | M27: =L27/$L$28 -> 0.039899392 | N27: =K27/$K$28 -> 0.058465881
B28: TOTAL | D28: =SUM(D10:D27) -> 347162.25 | E28: =SUM(E10:E27) -> 943969.83 | F28: =SUM(F10:F27) -> 135624.99 | G28: =SUM(G10:G27) -> 350711.86 | H28: =SUM(H10:H27) -> 361380 | J28: =SUM(J11:J27) -> 2138848.9 | K28: =SUM(K11:K27) -> 2031906.5 | L28: =SUM(L11:L27) -> 39809529 | M28: =SUM(M11:M27) -> 1 | N28: =SUM(N11:N27) -> 1

Sheet DOOH - METRÔ
B2: PROGRAMAÇÃO - DOOH METRÔ
B4: =CAPA!D4 -> MINISTÉRIO DA EDUCAÇÃO
B5: =CAPA!D6 -> FIES 2026
B6: =CAPA!D8 -> JULHO DE 2026
B8: IDENTIFICADOR SISTEMA | C8: UF | D8: PRAÇA | E8: CÓD MUNICÍPIO | F8: VEÍCULO | G8: CNPJ | H8: LOCAL | I8: FORMATO | M8: PERÍODO DE VEICULAÇÃO | P8: QUANT. DE FACES | Q8: QTD. INS DIA | R8: TT. INS.PERÍODO | S8: VALOR TABELA | U8: DESC. % | V8: VALOR NEGOCIADO | X8: VALOR DESEMBOLSO 95% | Y8: COBERTURA PERÍODO(FLUXO) | Z8: IMPACTO PERÍODO | AA8: FONTE | AB8: CPM | AC8: CPI | AD8: REPRESENTANTE
I9: TIPO | J9: TIPO DE COMPRA | K9: AMBIENTE | L9: MATERIAL | M9: INICIAL | N9: FINAL | O9: TOTAL DE DIAS | S9: UNITÁRIO | T9: TOTAL | V9: UNITÁRIO | W9: TOTAL 100%
B11: 97390 | C11: DF | D11: BRASÍLIA | E11: 5300108 | F11: URBAN + | G11: 44.472.500/0001-00 | H11: Embarque, sentido Plano Piloto | I11: METRÔ | J11: CIRCUITO | K11: METRO/TREM | L11: 15" | M11: 46219 | N11: =M11+O11-1 -> 46220 | O11: 2 | P11: 1 | Q11: 4160 | R11: =Q11*O11*P11 -> 8320 | S11: 3.2 | T11: =S11*R11 -> 26624 | U11: 0.3 | V11: =S11-S11*U11 -> 2.24 | W11: =T11*(1-U11) -> 18636.8 | X11: =W11*0.95 -> 17704.96 | Y11: 7283 | Z11: =R11 -> 8320 | AA11: PRÓPRIA | AB11: =W11/(Z11)*1000 -> 2240 | AC11: =W11/(Z11) -> 2.24 | AD11: DIRETO
B12: 97390 | C12: DF | D12: BRASÍLIA | E12: 5300108 | F12: URBAN + | G12: 44.472.500/0001-00 | H12: Embarque, sentido Plano Piloto/Taguatinga/Ceilândia/Samambaia | I12: METRÔ | J12: CIRCUITO | K12: METRO/TREM | L12: 15" | M12: 46219 | N12: =M12+O12-1 -> 46220 | O12: 2 | P12: 1 | Q12: 4160 | R12: =Q12*O12*P12 -> 8320 | S12: 3.2 | T12: =S12*R12 -> 26624 | U12: 0.3 | V12: =S12-S12*U12 -> 2.24 | W12: =T12*(1-U12) -> 18636.8 | X12: =W12*0.95 -> 17704.96 | Y12: 9454 | Z12: =R12 -> 8320 | AA12: PRÓPRIA | AB12: =W12/(Z12)*1000 -> 2240 | AC12: =W12/(Z12) -> 2.24 | AD12: DIRETO
B13: 12237 | C13: DF | D13: BRASÍLIA | E13: 5300108 | F13: MOBTV | G13: 05.806.588/0001-99 | H13: ESTAÇÃO PRAÇA DO RELÓGIO | I13: METRÔ | J13: CIRCUITO | K13: METRO/TREM | L13: 15" | M13: 46219 | N13: =M13+O13-1 -> 46220 | O13: 2 | P13: 1 | Q13: 1000 | R13: =Q13*O13*P13 -> 2000 | S13: 3.2 | T13: =S13*R13 -> 6400 | U13: 0.3 | V13: =S13-S13*U13 -> 2.24 | W13: =T13*(1-U13) -> 4480 | X13: =W13*0.95 -> 4256 | Y13: 7283 | Z13: =R13 -> 2000 | AA13: PRÓPRIA | AB13: =W13/(Z13)*1000 -> 2240 | AC13: =W13/(Z13) -> 2.24 | AD13: DS MIDIA
B14: 12237 | C14: DF | D14: BRASÍLIA | E14: 5300108 | F14: MOBTV | G14: 05.806.588/0001-99 | H14: ESTAÇÃO BRT GAMA | I14: METRÔ | J14: CIRCUITO | K14: METRO/TREM | L14: 15" | M14: 46219 | N14: =M14+O14-1 -> 46220 | O14: 2 | P14: 2 | Q14: 1000 | R14: =Q14*O14*P14 -> 4000 | S14: 3.2 | T14: =S14*R14 -> 12800 | U14: 0.3 | V14: =S14-S14*U14 -> 2.24 | W14: =T14*(1-U14) -> 8960 | X14: =W14*0.95 -> 8512 | Y14: 9454 | Z14: =R14 -> 4000 | AA14: PRÓPRIA | AB14: =W14/(Z14)*1000 -> 2240 | AC14: =W14/(Z14) -> 2.24 | AD14: DS MIDIA
B15: 12237 | C15: DF | D15: BRASÍLIA | E15: 5300108 | F15: MOBTV | G15: 05.806.588/0001-99 | H15: ESTAÇÃO BRT SANTA MARIA | I15: METRÔ | J15: CIRCUITO | K15: METRO/TREM | L15: 15" | M15: 46219 | N15: =M15+O15-1 -> 46220 | O15: 2 | P15: 2 | Q15: 1000 | R15: =Q15*O15*P15 -> 4000 | S15: 3.2 | T15: =S15*R15 -> 12800 | U15: 0.3 | V15: =S15-S15*U15 -> 2.24 | W15: =T15*(1-U15) -> 8960 | X15: =W15*0.95 -> 8512 | Y15: 9454 | Z15: =R15 -> 4000 | AA15: PRÓPRIA | AB15: =W15/(Z15)*1000 -> 2240 | AC15: =W15/(Z15) -> 2.24 | AD15: DS MIDIA
B16: 12237 | C16: DF | D16: BRASÍLIA | E16: 5300108 | F16: MOBTV | G16: 05.806.588/0001-99 | H16: LED ESTAÇÃO CENTRAL DESEMBARQUE | I16: METRÔ | J16: CIRCUITO | K16: METRO/TREM | L16: 15" | M16: 46219 | N16: =M16+O16-1 -> 46220 | O16: 2 | P16: 2 | Q16: 820 | R16: =Q16*O16*P16 -> 3280 | S16: 4.9 | T16: =S16*R16 -> 16072 | U16: 0.3 | V16: =S16-S16*U16 -> 3.43 | W16: =T16*(1-U16) -> 11250.4 | X16: =W16*0.95 -> 10687.88 | Y16: 9454 | Z16: =R16 -> 3280 | AA16: PRÓPRIA | AB16: =W16/(Z16)*1000 -> 3430 | AC16: =W16/(Z16) -> 3.43 | AD16: DS MIDIA
B17: 12237 | C17: DF | D17: BRASÍLIA | E17: 5300108 | F17: MOBTV | G17: 05.806.588/0001-99 | H17: LED ESTAÇÃO CENTRAL EMBARQUE | I17: METRÔ | J17: CIRCUITO | K17: METRO/TREM | L17: 15" | M17: 46219 | N17: =M17+O17-1 -> 46220 | O17: 2 | P17: 2 | Q17: 800 | R17: =Q17*O17*P17 -> 3200 | S17: 4.9 | T17: =S17*R17 -> 15680 | U17: 0.3 | V17: =S17-S17*U17 -> 3.43 | W17: =T17*(1-U17) -> 10976 | X17: =W17*0.95 -> 10427.2 | Y17: 9454 | Z17: =R17 -> 3200 | AA17: PRÓPRIA | AB17: =W17/(Z17)*1000 -> 3430 | AC17: =W17/(Z17) -> 3.43 | AD17: DS MIDIA
B18: TOTAL - BRASÍLIA | Q18: =SUBTOTAL(9,Q11:Q17) -> 12940 | R18: =SUBTOTAL(9,R11:R17) -> 33120 | T18: =SUBTOTAL(9,T11:T17) -> 117000 | W18: =SUBTOTAL(9,W11:W17) -> 81900 | X18: =SUBTOTAL(9,X11:X17) -> 77805 | Z18: =SUBTOTAL(9,Z11:Z17) -> 33120 | AB18: =SUBTOTAL(9,AB11:AB17) -> 18060
B19: 27461 | C19: SP | D19: SÃO PAULO | E19: 3550308 | F19: MEDIA MEGAS | G19: 10.929.279/0001-46 | H19: Circuito 11 Estações | I19: METRÔ | J19: CIRCUITO | K19: METRO/TREM | L19: 15" | M19: 46219 | N19: =M19+O19-1 -> 46220 | O19: 2 | P19: 200 | Q19: 812 | R19: =Q19*O19*P19 -> 324800 | S19: 275000 | T19: =S19 -> 275000 | U19: 0.24 | V19: =S19-S19*U19 -> 209000 | W19: =T19*(1-U19) -> 209000 | X19: =W19*0.95 -> 198550 | Y19: 7283 | Z19: =R19 -> 324800 | AA19: PRÓPRIA | AB19: =V19/(Z19)*1000 -> 643.47291 | AC19: =V19/(Z19) -> 0.64347291 | AD19: DIRETO
B20: 86035 | C20: SP | D20: SÃO PAULO | E20: 3550308 | F20: ELETROMÍDIA - TV MINUTO | G20: 27.865.757/0091-50 | H20: Metrô SP - Circuito Interno De Trem Completo | I20: METRÔ | J20: CIRCUITO | K20: METRO/TREM | L20: 10" | M20: 46219 | N20: =M20+O20-1 -> 46220 | O20: 2 | P20: 3792 | Q20: 192 | R20: =Q20*O20*P20 -> 1456128 | S20: 93770.41 | T20: =S20 -> 93770.41 | U20: 0.4 | V20: =S20-S20*U20 -> 56262.246 | W20: =T20*(1-U20) -> 56262.246 | X20: =W20*0.95 -> 53449.134 | Y20: 2450000 | Z20: =R20 -> 1456128 | AA20: PRÓPRIA | AB20: =V20/(Z20)*1000 -> 38.638256 | AC20: =V20/(Z20) -> 0.038638256 | AD20: DIRETO
B21: TOTAL - SÃO PAULO | Q21: =SUBTOTAL(9,Q19:Q20) -> 1004 | R21: =SUBTOTAL(9,R19:R20) -> 1780928 | T21: =SUBTOTAL(9,T19:T20) -> 368770.41 | W21: =SUBTOTAL(9,W19:W20) -> 265262.25 | X21: =SUBTOTAL(9,X19:X20) -> 251999.13 | Z21: =SUBTOTAL(9,Z19:Z20) -> 1780928 | AB21: =SUBTOTAL(9,AB19:AB20) -> 682.11116
B22: 86035 | C22: RJ | D22: RIO DE JANEIRO | E22: 3304557 | F22: ELETROMIDIA | G22: 27.865.757/0091-50 | H22: Metrô Rio - Circuito Completo | I22: METRÔ | J22: CIRCUITO | K22: METRO/TREM | L22: 10" | M22: 46219 | N22: =M22+O22-1 -> 46220 | O22: 2 | P22: 273 | U22: 0.4 | X22: =W22*0.95 -> 0 | Y22: 12314061 | Z22: =R22 -> 0 | AA22: PRÓPRIA | AB22: =V22/(Z22)*1000 -> #DIV/0! | AC22: =V22/(Z22) -> #DIV/0! | AD22: DIRETO
B23: TOTAL - RIO DE JANEIRO | Q23: =SUBTOTAL(9,Q22:Q22) -> 0 | R23: =SUBTOTAL(9,R22:R22) -> 0 | T23: =SUBTOTAL(9,T22:T22) -> 0 | W23: =SUBTOTAL(9,W22:W22) -> 0 | X23: =SUBTOTAL(9,X22:X22) -> 0 | Z23: =SUBTOTAL(9,Z22:Z22) -> 0 | AB23: =SUBTOTAL(9,AB22:AB22) -> #DIV/0!
B24: TOTAL GERAL | Q24: =SUBTOTAL(9,Q11:Q23) -> 13944 | R24: =SUBTOTAL(9,R11:R23) -> 1814048 | T24: =SUBTOTAL(9,T11:T23) -> 485770.41 | W24: =SUBTOTAL(9,W11:W23) -> 347162.25 | X24: =SUBTOTAL(9,X11:X23) -> 329804.13 | Z24: =SUBTOTAL(9,Z18:Z23) -> 1780928 | AB24: =SUBTOTAL(9,AB18:AB23) -> #DIV/0!
B25: OBSERVAÇÃO:
B27: VEÍCULO | D27: QTD DE INSERÇÕES | E27: DADOS DE IMPACTO | F27: VALOR TABELA | G27: VALOR NEGOCIADO 100% | H27: VALOR DESEMBOLSO 95% | I27: RENTABILIDADE %
B28: URBAN + | D28: =SUMIF(F:F,B28,R:R) -> 16640 | E28: =SUMIF(F:F,B28,Z:Z) -> 16640 | F28: =SUMIF($F$11:$F$22,B28,$T$11:$T$23) -> 53248 | G28: =SUMIF($F$11:$F$22,B28,$W$11:$W$23) -> 37273.6 | H28: =G28*0.95 -> 35409.92 | I28: =1-H28/F28 -> 0.335
B29: MOBTV | D29: =SUMIF(F:F,B29,R:R) -> 16480 | E29: =SUMIF(F:F,B29,Z:Z) -> 16480 | F29: =SUMIF($F$11:$F$22,B29,$T$11:$T$23) -> 63752 | G29: =SUMIF($F$11:$F$22,B29,$W$11:$W$23) -> 44626.4 | H29: =G29*0.95 -> 42395.08 | I29: =1-H29/F29 -> 0.335
B30: MEDIA MEGAS | D30: =SUMIF(F:F,B30,R:R) -> 324800 | E30: =SUMIF(F:F,B30,Z:Z) -> 324800 | F30: =SUMIF($F$11:$F$22,B30,$T$11:$T$23) -> 275000 | G30: =SUMIF($F$11:$F$22,B30,$W$11:$W$23) -> 209000 | H30: =G30*0.95 -> 198550 | I30: =1-H30/F30 -> 0.278
B31: ELETROMÍDIA - TV MINUTO | D31: =SUMIF(F:F,B31,R:R) -> 1456128 | E31: =SUMIF(F:F,B31,Z:Z) -> 1456128 | F31: =SUMIF($F$11:$F$22,B31,$T$11:$T$23) -> 93770.41 | G31: =SUMIF($F$11:$F$22,B31,$W$11:$W$23) -> 56262.246 | H31: =G31*0.95 -> 53449.134 | I31: =1-H31/F31 -> 0.43
B32: ELETROMIDIA | D32: =SUMIF(F:F,B32,R:R) -> 0 | E32: =SUMIF(F:F,B32,Z:Z) -> 0 | F32: =SUMIF($F$11:$F$22,B32,$T$11:$T$23) -> 0 | G32: =SUMIF($F$11:$F$22,B32,$W$11:$W$23) -> 0 | H32: =G32*0.95 -> 0 | I32: =1-H32/F32 -> #DIV/0!
D33: =SUM(D28:D32) -> 1814048 | E33: =SUM(E28:E32) -> 1814048 | F33: =SUM(F28:F32) -> 485770.41 | G33: =SUM(G28:G32) -> 347162.25 | H33: =SUM(H28:H32) -> 329804.13
B36: AGENCIA | C36: VALOR 100% | D36: VALOR 95%
B37: CALIA | C37: =SUMIF($A$18:$A$23,B37,$W$18:$W$24) -> 0 | D37: =C37*0.95 -> 0
B38: SA | C38: =SUMIF($A$18:$A$23,B38,$W$18:$W$24) -> 0 | D38: =C38*0.95 -> 0
B39: DE BRITO | C39: =SUMIF($A$18:$A$23,B39,$W$18:$W$24) -> 0 | D39: =C39*0.95 -> 0

Sheet DOOH - MUB
B2: PROGRAMAÇÃO - DOOH MOBILIÁRIO URBANO
AH3: ,
B4: =RESUMO!C5 -> MINISTÉRIO DA EDUCAÇÃO
B5: =RESUMO!C6 -> FIES 2026
B6: =RESUMO!C7 -> JULHO DE 2026
B8: IDENTIFICADOR SISTEMA | C8: UF | D8: PRAÇA | E8: CÓD MUNICÍPIO | F8: VEÍCULO | G8: CNPJ | H8: LOCAL | I8: FORMATO | M8: PERÍODO DE VEICULAÇÃO | P8: QUANT. DE FACES | Q8: QTD. INS DIA | R8: TT. INS.PERÍODO | S8: QTD DE COTAS CONTRATADAS | T8: VALOR TABELA | V8: DESC. % | W8: VALOR NEGOCIADO | Y8: VALOR DESEMBOLSO 95% | Z8: COBERTURA PERÍODO(FLUXO) | AA8: IMPACTO PERÍODO | AB8: FONTE | AC8: CPM | AD8: CPI | AE8: REPRESENTANTE
I9: TIPO | J9: TIPO DE COMPRA | K9: AMBIENTE | L9: MATERIAL | M9: INICIAL | N9: FINAL | O9: TOTAL DE DIAS | T9: UNITÁRIO | U9: TOTAL | W9: UNITÁRIO | X9: TOTAL 100%
B11: 12323 | C11: DF | D11: BRASÍLIA | E11: 5300108 | F11: VISUPLAC | G11: 02.306.218/0001-02 | H11: CIRCUITO EMPIRE STATE | I11: MUB DIGITAL | J11: CIRCUITO | K11: VIAS DE ALTO FLUXO | L11: 10" | M11: 46219 | N11: =M11+O11-1 -> 46220 | O11: 2 | P11: 132 | Q11: 360 | R11: =Q11*P11*O11 -> 95040 | S11: 1 | T11: =279840/7*O11 -> 79954.286 | U11: =T11 -> 79954.286 | V11: 0.15 | W11: =T11-T11*V11 -> 67961.143 | X11: =U11*(1-V11) -> 67961.143 | Y11: =X11*0.95 -> 64563.086 | Z11: - | AA11: =R11 -> 95040 | AB11: PRÓPRIA | AC11: =X11/(AA11+AA12)*1000 -> 715.07937 | AD11: =X11/(AA11+AA12) -> 0.71507937 | AE11: MOSAICO
B12: TOTAL - DISTRITO FEDERAL | R12: =SUBTOTAL(9,R11:R11) -> 95040 | X12: =SUBTOTAL(9,X11:X11) -> 67961.143 | Y12: =X12*0.95 -> 64563.086
B13: 100158 | C13: RJ | D13: RIO DE JANEIRO | E13: 3304557 | F13: PLUREX | G13: 30.307.086/0001-60 | H13: diversos (verificar endereços abaixo) | I13: BANCA DIGITAL | J13: PERÍODO | K13: VIAS DE ALTO FLUXO | L13: 10" | M13: 46219 | N13: =M13+O13-1 -> 46220 | O13: 2 | P13: 10 | Q13: 855 | R13: =O13*P13*Q13 -> 17100 | S13: 1 | T13: 3.2 | U13: =T13*R13 -> 54720 | V13: 0.55 | W13: =T13-(T13*V13) -> 1.44 | X13: =U13-(U13*V13) -> 24624 | Y13: =X13*0.95 -> 23392.8 | Z13: 336119 | AA13: =R13 -> 17100 | AB13: NÃO INFORMADO | AC13: =X13/(AA13+AA14)*1000 -> 1440 | AD13: =X13/(AA13+AA14) -> 1.44 | AE13: BI GROUP
B14: TOTAL - RIO DE JANEIRO | R14: =SUBTOTAL(9,R13:R13) -> 17100 | X14: =SUBTOTAL(9,X13:X13) -> 24624 | Y14: =X14*0.95 -> 23392.8
B15: 70547 | C15: MG | D15: BELO HORIZONTE | E15: 3106200 | F15: DESTAKE | G15: 07.923.942/0001-90 | H15: diversos (verificar endereços abaixo) | I15: MUB DIGITAL | J15: POR FACE | K15: VIAS DE ALTO FLUXO | L15: 10" | M15: 46219 | N15: =M15+O15-1 -> 46220 | O15: 2 | P15: 25 | Q15: 4800 | R15: =Q15*P15*O15 -> 240000 | S15: 4 | T15: 7752 | U15: =T15*P15 -> 193800 | V15: 0.33 | W15: =T15-T15*V15 -> 5193.84 | X15: =U15*(1-V15) -> 129846 | Y15: =X15*0.95 -> 123353.7 | Z15: 115140.29 | AA15: =Z15*O15 -> 230280.57 | AB15: PRÓPRIA | AC15: =X15/(AA15+AA16)*1000 -> 563.85999 | AD15: =X15/(AA15+AA16) -> 0.56385999 | AE15: MIDIA MAIS
B16: TOTAL - MINAS GERAIS | R16: =SUBTOTAL(9,R15:R15) -> 240000 | X16: =SUBTOTAL(9,X15:X15) -> 129846 | Y16: =X16*0.95 -> 123353.7
B17: 41033 | C17: SP | D17: SÃO PAULO | E17: 3550308 | F17: ELETROMIDIA | G17: 17.104.815/0001-13 | H17: Abrigos São Paulo | I17: MUB DIGITAL | J17: POR FACE | K17: VIAS DE ALTO FLUXO | L17: 10" | M17: 46219 | N17: 46217 | O17: 2 | P17: 100 | Q17: 732 | R17: =Q17*P17*O17 -> 146400 | S17: 1 | T17: 213801.19 | U17: =T17 -> 213801.19 | V17: 0.4 | W17: =T17-T17*V17 -> 128280.71 | X17: =U17*(1-V17) -> 128280.71 | Y17: =X17*0.95 -> 121866.68 | Z17: 602818.97 | AA17: =Z17*P17 -> 60281897 | AB17: PRÓPRIA | AC17: =X17/(AA17+AA18)*1000 -> 2.1280139 | AD17: =X17/(AA17+AA18) -> 0.0021280139 | AE17: STREET MÍDIA
B18: TOTAL - SÃO PAULO | R18: =R17 -> 146400 | X18: =SUBTOTAL(9,X17) -> 128280.71 | Y18: =X18*0.95 -> 121866.68
B20: TOTAL GERAL | R20: =SUBTOTAL(9,R11:R18) -> 644940 | U20: =SUM(U11:U18) -> 542275.48 | X20: =SUBTOTAL(9,X11:X18) -> 350711.86 | Y20: =X20*0.95 -> 333176.26 | AA20: =SUM(AA11:AA17) -> 60624317
B21: OBSERVAÇÃO:
B23: VEÍCULO | D23: QTD DE INSERÇÕES | E23: DADOS DE IMPACTO | F23: VALOR TABELA | G23: VALOR NEGOCIADO 100% | H23: VALOR DESEMBOLSO 95% | I23: RENTABILIDADE %
B24: VISUPLAC | D24: =SUMIF($F$11:$F$17,B24,$R$11:$R$17) -> 95040 | E24: =SUMIF($F$11:$F$17,B24,$AA$11:$AA$17) -> 95040 | F24: =SUMIF($F$11:$F$17,B24,$U$11:$U$17) -> 79954.286 | G24: =SUMIF($F$11:$F$17,B24,$X$11:$X$17) -> 67961.143 | H24: =G24*0.95 -> 64563.086 | I24: =1-H24/F24 -> 0.1925
B25: PLUREX | D25: =SUMIF($F$11:$F$17,B25,$R$11:$R$17) -> 17100 | E25: =SUMIF($F$11:$F$17,B25,$AA$11:$AA$17) -> 17100 | F25: =SUMIF($F$11:$F$17,B25,$U$11:$U$17) -> 54720 | G25: =SUMIF($F$11:$F$17,B25,$X$11:$X$17) -> 24624 | H25: =G25*0.95 -> 23392.8 | I25: =1-H25/F25 -> 0.5725
B26: DESTAKE | D26: =SUMIF($F$11:$F$17,B26,$R$11:$R$17) -> 240000 | E26: =SUMIF($F$11:$F$17,B26,$AA$11:$AA$17) -> 230280.57 | F26: =SUMIF($F$11:$F$17,B26,$U$11:$U$17) -> 193800 | G26: =SUMIF($F$11:$F$17,B26,$X$11:$X$17) -> 129846 | H26: =G26*0.95 -> 123353.7 | I26: =1-H26/F26 -> 0.3635
B27: ELETROMIDIA | D27: =SUMIF($F$11:$F$17,B27,$R$11:$R$17) -> 146400 | E27: =SUMIF($F$11:$F$17,B27,$AA$11:$AA$17) -> 60281897 | F27: =SUMIF($F$11:$F$17,B27,$U$11:$U$17) -> 213801.19 | G27: =SUMIF($F$11:$F$17,B27,$X$11:$X$17) -> 128280.71 | H27: =G27*0.95 -> 121866.68 | I27: =1-H27/F27 -> 0.43
D28: =SUM(D24:D27) -> 498540 | E28: =SUM(E24:E27) -> 60624317 | F28: =SUM(F24:F27) -> 542275.48 | G28: =SUM(G24:G27) -> 350711.86 | H28: =SUM(H24:H27) -> 333176.26
B31: AGENCIA | C31: VALOR 100% | D31: VALOR 95%
B32: CALIA | C32: =SUMIF($A$11:$A$17,B32,$X$11:$X$19) -> 0 | D32: =C32*0.95 -> 0
B33: SA | C33: =SUMIF($A$11:$A$17,B33,$X$11:$X$19) -> 0 | D33: =C33*0.95 -> 0
B34: DE BRITO | C34: =SUMIF($A$11:$A$17,B34,$X$11:$X$19) -> 0 | D34: =C34*0.95 -> 0
B37: LSITA DE BANCAS
B38: AV AFONSO PENA, 1005 - CENTRO
B39: AV. AFONSO PENA, 1709 - FUNCIONÁRIOS
B40: ALVARES CABRAL, 17 - CENTRO
B41: AV. AMAZONAS, 1837 - SANTO AGOSTINHO
B42: AV CRISTIANO MACHADO, 11936 - JULIANA
B43: AV CRISTIANO MACHADO.2320 - CIDADE NOVA
B44: AV CRISTÁVÃO COLOMBO, 277 - SAVASSI
B45: AV DO CONTORNO, 1343 - FLORESTA
B46: AV DO CONTORNO, 3946 - SANTA EFIGÊNIA
B47: AV DO CONTORNO, 6846 - LOURDES
B48: AV DOS BANDEIRANTES, 60, SION
... B69: RUA RIO GRANDE DO SUL, 758 - BARRO PRETO

Sheet DOOH - ESTABELECIMENTOS
B2: PROGRAMAÇÃO - DOOH ESTABELECIMENTOS
B4: =RESUMO!C5 -> MINISTÉRIO DA EDUCAÇÃO
B5: =RESUMO!C6 -> FIES 2026
B6: =RESUMO!C7 -> JULHO DE 2026
B8: IDENTIFICADOR SISTEMA | C8: UF | D8: PRAÇA | E8: CÓD MUNICÍPIO | F8: VEÍCULO | G8: CNPJ | H8: LOCAL | I8: FORMATO | M8: PERÍODO DE VEICULAÇÃO | P8: MATERIAL | Q8: QTD. INS DIA | R8: TT. INS. | S8: VALOR TABELA | U8: DESC. % | V8: VALOR NEGOCIADO | X8: VALOR DESEMBOLSO 95% | Y8: COBERTURA PERÍODO (FLUXO) | Z8: IMPACTO PERÍODO | AA8: CPI | AB8: CPM | AC8: RENTABILIDADE | AD8: REPRESENTANTE
I9: TIPO | J9: TIPO DE COMPRA | K9: AMBIENTE | L9: QUANT. | M9: INICIAL | N9: FINAL | O9: TOTAL DE DIAS | S9: UNITÁRIO | T9: TOTAL | V9: UNITÁRIO | W9: TOTAL 100%
B11: 57519 | C11: PE | D11: RECIFE | F11: INSIGHT MIDIA | G11: 18.619.705/0001-57 | H11: LOTÉRICAS | I11: MIDIA EM LOTERICA | J11: INSERÇÕES | K11: LOTÉRICAS | L11: 70 | M11: 46219 | N11: =M11+O11-1 -> 46220 | O11: 2 | P11: 15" | Q11: 300 | R11: =Q11*O11 -> 600 | S11: 80 | T11: =S11*R11 -> 48000 | U11: 0.36 | V11: =S11-S11*U11 -> 51.2 | W11: =T11*(1-U11) -> 30720 | X11: =W11*0.95 -> 29184 | Y11: 80888.889 | Z11: =Y11*O11 -> 161777.78 | AA11: =W11/(Z11+#REF!) -> #REF! | AB11: =W11/(Z11+#REF!)*1000 -> #REF! | AC11: =1-(W11/((T11+#REF!))) -> #REF! | AD11: INSIGHT
B12: TOTAL - PERNAMBUCO | L12: =SUBTOTAL(9,L11:L11) -> 70 | R12: =SUBTOTAL(9,R11:R11) -> 600 | W12: =SUBTOTAL(9,W11:W11) -> 30720 | X12: =W12*0.95 -> 29184 | AB12: =SUBTOTAL(9,AB11:AB11) -> #REF!
B13: 57519 | C13: CE | D13: FORTALEZA | F13: INSIGHT MIDIA | G13: 18.619.705/0001-57 | H13: LOTÉRICAS | I13: MIDIA EM LOTERICA | J13: INSERÇÕES | K13: LOTÉRICAS | L13: 70 | M13: 46219 | N13: =M13+O13-1 -> 46220 | O13: 2 | P13: 15" | Q13: 300 | R13: =Q13*O13 -> 600 | S13: 70 | T13: =S13*R13 -> 42000 | U13: 0.36 | V13: =S13-S13*U13 -> 44.8 | W13: =T13*(1-U13) -> 26880 | X13: =W13*0.95 -> 25536 | Y13: 80888.889 | Z13: =Y13*O13 -> 161777.78 | AA13: =W13/(Z13+#REF!) -> #REF! | AB13: =W13/(Z13+#REF!)*1000 -> #REF! | AC13: =1-(W13/((T13+#REF!))) -> #REF! | AD13: INSIGHT
B14: TOTAL - CEARA | L14: =SUBTOTAL(9,L13:L13) -> 70 | R14: =SUBTOTAL(9,R13:R13) -> 600 | W14: =SUBTOTAL(9,W13:W13) -> 26880 | X14: =W14*0.95 -> 25536 | AB14: =SUBTOTAL(9,AB13:AB13) -> #REF!
B15: 57519 | C15: DF | D15: BRASÍLIA | F15: INSIGHT MIDIA | G15: 18.619.705/0001-57 | H15: LOTÉRICAS | I15: MIDIA EM LOTERICA | J15: INSERÇÕES | K15: LOTÉRICAS | L15: 70 | M15: 46219 | N15: =M15+O15-1 -> 46220 | O15: 2 | P15: 15" | Q15: 300 | R15: =Q15*O15 -> 600 | S15: 150 | T15: =S15*R15 -> 90000 | U15: 0.36 | V15: =S15-S15*U15 -> 96 | W15: =T15*(1-U15) -> 57600 | X15: =W15*0.95 -> 54720 | Y15: 80888.889 | Z15: =Y15*O15 -> 161777.78 | AA15: =W15/(Z15+#REF!) -> #REF! | AB15: =W15/(Z15+#REF!)*1000 -> #REF! | AC15: =1-(W15/((T15+#REF!))) -> #REF! | AD15: INSIGHT
B16: TOTAL - DISTRITO FEDERAL | L16: =SUBTOTAL(9,L15:L15) -> 70 | R16: =SUBTOTAL(9,R15:R15) -> 600 | W16: =SUBTOTAL(9,W15:W15) -> 57600 | X16: =W16*0.95 -> 54720 | AB16: =SUBTOTAL(9,AB15:AB15) -> #REF!
B17: 57519 | C17: SP | D17: SÃO PAULO | E17: 3550308 | F17: INSIGHT MIDIA | G17: 18.619.705/0001-57 | H17: LOTÉRICAS | I17: MIDIA EM LOTERICA | J17: INSERÇÕES | K17: LOTÉRICAS | L17: 70 | M17: 46219 | N17: =M17+O17-1 -> 46220 | O17: 2 | P17: 15" | Q17: 300 | R17: =Q17*O17 -> 600 | S17: 199 | T17: =S17*R17 -> 119400 | U17: 0.36 | V17: =S17-S17*U17 -> 127.36 | W17: =T17*(1-U17) -> 76416 | X17: =W17*0.95 -> 72595.2 | Y17: 80888.889 | Z17: =Y17*O17 -> 161777.78 | AA17: =W17/(Z17+#REF!) -> #REF! | AB17: =W17/(Z17+#REF!)*1000 -> #REF! | AC17: =1-(W17/((T17+#REF!))) -> #REF! | AD17: INSIGHT
B18: TOTAL - SÃO PAULO | L18: =SUBTOTAL(9,L17:L17) -> 70 | R18: =SUBTOTAL(9,R17:R17) -> 600 | W18: =SUBTOTAL(9,W17:W17) -> 76416 | X18: =W18*0.95 -> 72595.2 | AB18: =SUBTOTAL(9,AB17:AB17) -> #REF!
B19: 57519 | C19: BA | D19: SALVADOR | F19: INSIGHT MIDIA | G19: 18.619.705/0001-57 | H19: LOTÉRICAS | I19: MIDIA EM LOTERICA | J19: INSERÇÕES | K19: LOTÉRICAS | L19: 70 | M19: 46219 | N19: =M19+O19-1 -> 46220 | O19: 2 | P19: 15" | Q19: 300 | R19: =Q19*O19 -> 600 | S19: 65 | T19: =S19*R19 -> 39000 | U19: 0.36 | V19: =S19-S19*U19 -> 41.6 | W19: =T19*(1-U19) -> 24960 | X19: =W19*0.95 -> 23712 | Y19: 80888.889 | Z19: =Y19*O19 -> 161777.78 | AA19: =W19/(Z19+#REF!) -> #REF! | AB19: =W19/(Z19+#REF!)*1000 -> #REF! | AC19: =1-(W19/((T19+#REF!))) -> #REF! | AD19: INSIGHT
B20: TOTAL - BAHIA | L20: =SUBTOTAL(9,L19:L19) -> 70 | R20: =SUBTOTAL(9,R19:R19) -> 600 | W20: =SUBTOTAL(9,W19:W19) -> 24960 | X20: =W20*0.95 -> 23712 | AB20: =SUBTOTAL(9,AB19:AB19) -> #REF!
B21: 57519 | C21: PR | D21: CURITIBA | F21: INSIGHT MIDIA | G21: 18.619.705/0001-57 | H21: LOTÉRICAS | I21: MIDIA EM LOTERICA | J21: INSERÇÕES | K21: LOTÉRICAS | L21: 70 | M21: 46219 | N21: =M21+O21-1 -> 46220 | O21: 2 | P21: 15" | Q21: 300 | R21: =Q21*O21 -> 600 | S21: 70 | T21: =S21*R21 -> 42000 | U21: 0.36 | V21: =S21-S21*U21 -> 44.8 | W21: =T21*(1-U21) -> 26880 | X21: =W21*0.95 -> 25536 | Y21: 80888.889 | Z21: =Y21*O21 -> 161777.78 | AA21: =W21/(Z21+#REF!) -> #REF! | AB21: =W21/(Z21+#REF!)*1000 -> #REF! | AC21: =1-(W21/((T21+#REF!))) -> #REF! | AD21: INSIGHT
B22: TOTAL - PARANA | L22: =SUBTOTAL(9,L21:L21) -> 70 | R22: =SUBTOTAL(9,R21:R21) -> 600 | W22: =SUBTOTAL(9,W21:W21) -> 26880 | X22: =W22*0.95 -> 25536 | AB22: =SUBTOTAL(9,AB21:AB21) -> #REF!
B23: 83840 | C23: PA | D23: BELEM | F23: BEEP MIDIA | G23: 42.448.723/0001-06 | H23: LOTÉRICAS | I23: MIDIA EM LOTERICA | J23: INSERÇÕES | K23: LOTÉRICAS | L23: 30 | M23: 46219 | N23: =M23+O23-1 -> 46220 | O23: 2 | P23: 15" | Q23: 300 | R23: =Q23*O23 -> 600 | S23: 109 | T23: =S23*R23 -> 65400 | U23: 0.38 | V23: =S23-S23*U23 -> 67.58 | W23: =T23*(1-U23) -> 40548 | X23: =W23*0.95 -> 38520.6 | Y23: 80888.889 | Z23: =Y23*O23 -> 161777.78 | AA23: =W23/(Z23+#REF!) -> #REF! | AB23: =W23/(Z23+#REF!)*1000 -> #REF! | AC23: =1-(W23/((T23+#REF!))) -> #REF! | AD23: INSIGHT
B24: TOTAL - PARA | L24: =SUBTOTAL(9,L23:L23) -> 30 | R24: =SUBTOTAL(9,R23:R23) -> 600 | W24: =SUBTOTAL(9,W23:W23) -> 40548 | X24: =W24*0.95 -> 38520.6 | AB24: =SUBTOTAL(9,AB23:AB23) -> #REF!
B25: 83840 | C25: RJ | D25: RIO DE JANEIRO | F25: BEEP MIDIA | G25: 42.448.723/0001-06 | H25: LOTÉRICAS | I25: MIDIA EM LOTERICA | J25: INSERÇÕES | K25: LOTÉRICAS | L25: 51 | M25: 46219 | N25: =M25+O25-1 -> 46220 | O25: 2 | P25: 15" | Q25: 300 | R25: =Q25*O25 -> 600 | S25: 129 | T25: =S25*R25 -> 77400 | U25: 0.38 | V25: =S25-S25*U25 -> 79.98 | W25: =T25*(1-U25) -> 47988 | X25: =W25*0.95 -> 45588.6 | Y25: 80888.889 | Z25: =Y25*O25 -> 161777.78 | AA25: =W25/(Z25+#REF!) -> #REF! | AB25: =W25/(Z25+#REF!)*1000 -> #REF! | AC25: =1-(W25/((T25+#REF!))) -> #REF! | AD25: INSIGHT
B26: TOTAL - RIO DE JANEIRO | L26: =SUBTOTAL(9,L25:L25) -> 51 | R26: =SUBTOTAL(9,R25:R25) -> 600 | W26: =SUBTOTAL(9,W25:W25) -> 47988 | X26: =W26*0.95 -> 45588.6 | AB26: =SUBTOTAL(9,AB25:AB25) -> #REF!
B27: 83840 | C27: MA | D27: SÃO LUIS | F27: BEEP MIDIA | G27: 42.448.723/0001-06 | H27: LOTÉRICAS | I27: MIDIA EM LOTERICA | J27: INSERÇÕES | K27: LOTÉRICAS | L27: 26 | M27: 46219 | N27: =M27+O27-1 -> 46220 | O27: 2 | P27: 15" | Q27: 300 | R27: =Q27*O27 -> 600 | S27: 79 | T27: =S27*R27 -> 47400 | U27: 0.38 | V27: =S27-S27*U27 -> 48.98 | W27: =T27*(1-U27) -> 29388 | X27: =W27*0.95 -> 27918.6 | Y27: 80888.889 | Z27: =Y27*O27 -> 161777.78 | AA27: =W27/(Z27+#REF!) -> #REF! | AB27: =W27/(Z27+#REF!)*1000 -> #REF! | AC27: =1-(W27/((T27+#REF!))) -> #REF! | AD27: INSIGHT
B28: TOTAL - MARANHAO | L28: =SUBTOTAL(9,L27:L27) -> 26 | R28: =SUBTOTAL(9,R27:R27) -> 600 | W28: =SUBTOTAL(9,W27:W27) -> 29388 | X28: =W28*0.95 -> 27918.6 | AB28: =SUBTOTAL(9,AB27:AB27) -> #REF!
B29: TOTAL GERAL | L29: =SUBTOTAL(9,L11:L28) -> 527 | R29: =SUBTOTAL(9,R11:R28) -> 5400 | T29: =SUBTOTAL(9,T11:T28) -> 570600 | W29: =SUBTOTAL(9,W11:W28) -> 361380 | X29: =W29*0.95 -> 343311 | Z29: =SUM(Z11:Z12) -> 161777.78
B31: OBSERVAÇÕES: NÃO HÁ VEICULAÇÃO AOS DOMINGOS
B34: VEICULO | D34: INS | E34: VALOR 100% | F34: TOTAL 100% | G34: DESEMBOLSO 95%
B35: INSIGHT MIDIA | D35: =SUMIF(F$11:$F28,B35,R$11:$R28) -> 3600 | E35: =SUMIF($F$11:$AD$29,B35,$W$11:$W$12) -> 243456 | F35: =SUMIF($F$11:$F$28,B35,$W$11:$W$28) -> 243456 | G35: =SUMIF($F$11:$F$27,B35,$X$11:$X$28) -> 231283.2
B36: BEEP MIDIA | D36: =SUMIF(F$11:$F29,B36,R$11:$R29) -> 1800 | E36: =SUMIF($F$11:$AD$29,B36,$W$11:$W$12) -> 117924 | F36: =SUMIF($F$11:$F$28,B36,$W$11:$W$28) -> 117924 | G36: =SUMIF($F$11:$F$27,B36,$X$11:$X$28) -> 112027.8
B37: TOTAL | D37: =D36 -> 1800 | E37: =SUM(E36:E36) -> 117924 | F37: =F35+F36 -> 361380 | G37: =G35+G36 -> 343311
B40: AGENCIA | D40: VALOR 100% | E40: VALOR 95%
B41: CALIA | D41: =SUMIF($A$11:$A$12,B41,$W$11:$W$12) -> 0 | E41: =D41*0.95 -> 0
B42: SA | D42: =SUMIF($A$11:$A$12,B42,$W$11:$W$12) -> 0 | E42: =D42*0.95 -> 0
B43: DE BRITO | D43: =SUMIF($A$11:$A$12,B43,$W$11:$W$12) -> 0 | E43: =D43*0.95 -> 0

Sheet DOOH - PAINEL
B2: PROGRAMAÇÃO - DOOH PAINEL ELETRÔNICO
B4: =CAPA!D4 -> MINISTÉRIO DA EDUCAÇÃO
B5: =CAPA!D6 -> FIES 2026
B6: =CAPA!D8 -> JULHO DE 2026
B8: IDENTIFICADOR SISTEMA | C8: UF | D8: PRAÇA | E8: CÓD MUNICÍPIO | F8: VEÍCULO | G8: CNPJ | H8: LOCAL | I8: FORMATO | M8: PERÍODO DE VEICULAÇÃO | P8: QUANT. DE FACES | Q8: QTD. INS DIA | R8: TT. INS.PERÍODO | S8: QTD DE COTAS CONTRATADAS | T8: VALOR TABELA | V8: DESC. % | W8: VALOR NEGOCIADO | Y8: VALOR DESEMBOLSO 95% | Z8: COBERTURA PERÍODO (FLUXO) | AA8: IMPACTO PERÍODO | AB8: CPI | AC8: CPM | AD8: REPRESENTANTE
I9: TIPO | J9: TIPO DE COMPRA | K9: AMBIENTE | L9: MATERIAL | M9: INICIAL | N9: FINAL | O9: TOTAL DE DIAS | T9: UNITÁRIO | U9: TOTAL | W9: UNITÁRIO | X9: TOTAL 100%
B11: 12084 | C11: PE | D11: RECIFE | E11: 2611606 | F11: WE SUPER OOH | G11: 13.045.189/0005-70 | H11: Av. Conselheiro Rosa e Silva, 212 | I11: PAINEL ELETRÔNICO | J11: MENSAL PROPORCIONAL | K11: VIAS DE ALTO FLUXO | L11: 10" | M11: 46219 | N11: =M11+O11-1 -> 46220 | O11: 2 | P11: 1 | Q11: =360*2 -> 720 | R11: =Q11*P11*O11 -> 1440 | S11: 2 | T11: 2649.86 | U11: =T11*S11 -> 5299.72 | V11: 0.15 | W11: =T11-T11*V11 -> 2252.381 | X11: =U11*(1-V11) -> 4504.762 | Y11: =X11*0.95 -> 4279.5239 | Z11: 252578 | AA11: =R11 -> 1440 | AB11: =X11/(AA11) -> 3.1283069 | AC11: =X11/(AA11)*1000 -> 3128.3069 | AD11: MOSAICO
B12: 12084 | C12: PE | D12: RECIFE | E12: 2611606 | F12: WE SUPER OOH | G12: 13.045.189/0005-70 | H12: Av. 17 de Agosto, 823 | I12: PAINEL ELETRÔNICO | J12: MENSAL PROPORCIONAL | K12: VIAS DE ALTO FLUXO | L12: 10" | M12: 46219 | N12: =M12+O12-1 -> 46220 | O12: 2 | P12: 1 | Q12: =360*2 -> 720 | R12: =Q12*P12*O12 -> 1440 | S12: 2 | T12: 2649.86 | U12: 5299.72 | V12: 0.15 | W12: =T12-T12*V12 -> 2252.381 | X12: =U12*(1-V12) -> 4504.762 | Y12: =X12*0.95 -> 4279.5239 | Z12: 209499 | AA12: =R12 -> 1440 | AB12: =X12/(AA12) -> 3.1283069 | AC12: =X12/(AA12)*1000 -> 3128.3069 | AD12: MOSAICO
B13: 12084 | C13: PE | D13: RECIFE | E13: 2611606 | F13: WE SUPER OOH | G13: 13.045.189/0005-70 | H13: Rua Ernesto de Paula Santos esquina com a Av. Engenheiro Domingos Ferreira, 4140 | I13: PAINEL ELETRÔNICO | J13: MENSAL PROPORCIONAL | K13: VIAS DE ALTO FLUXO | L13: 10" | M13: 46219 | N13: =M13+O13-1 -> 46220 | O13: 2 | P13: 1 | Q13: =360*2 -> 720 | R13: =Q13*P13*O13 -> 1440 | S13: 2 | T13: 2649.86 | U13: 5299.72 | V13: 0.15 | W13: =T13-T13*V13 -> 2252.381 | X13: =U13*(1-V13) -> 4504.762 | Y13: =X13*0.95 -> 4279.5239 | Z13: 70000 | AA13: =R13 -> 1440 | AB13: =X13/(AA13) -> 3.1283069 | AC13: =X13/(AA13)*1000 -> 3128.3069 | AD13: MOSAICO
B14: 82219 | C14: PE | D14: RECIFE | E14: 2611606 | F14: INTELICOM | H14: Av. Conselheiro Aguiar acesso Shopping -Pina | I14: PAINEL ELETRÔNICO | J14: MENSAL PROPORCIONAL | K14: VIAS DE ALTO FLUXO | L14: 10" | M14: 46219 | N14: =M14+O14-1 -> 46220 | O14: 2 | P14: 1 | Q14: 945 | R14: =Q14*P14*O14 -> 1890 | S14: 1 | T14: =27001*0.7/7*O14 -> 5400.2 | U14: =T14 -> 5400.2 | V14: 0 | W14: =T14-T14*V14 -> 5400.2 | X14: =U14*(1-V14) -> 5400.2 | Y14: =X14*0.95 -> 5130.19 | Z14: 70000 | AA14: =R14 -> 1890 | AB14: =X14/(AA14+AA16) -> 1.8557388 | AC14: =X14/(AA14+AA16)*1000 -> 1855.7388 | AD14: DIRETO
B15: 82219 | C15: PE | D15: RECIFE | E15: 2611606 | F15: INTELICOM | H15: Av. Conselheiro Rosa e Silva - Aflitos | I15: PAINEL ELETRÔNICO | J15: MENSAL PROPORCIONAL | K15: VIAS DE ALTO FLUXO | L15: 10" | M15: 46219 | N15: =M15+O15-1 -> 46220 | O15: 2 | P15: 1 | Q15: 945 | R15: =Q15*P15*O15 -> 1890 | S15: 1 | T15: =27001*0.7/7*O15 -> 5400.2 | U15: =T15 -> 5400.2 | V15: 0 | W15: =T15-T15*V15 -> 5400.2 | X15: =U15*(1-V15) -> 5400.2 | Y15: =X15*0.95 -> 5130.19 | Z15: 70000 | AA15: =R15 -> 1890 | AB15: =X15/(AA15+AA23) -> 0.83208012 | AC15: =X15/(AA15+AA23)*1000 -> 832.08012 | AD15: DIRETO
B16: 82219 | C16: PE | D16: RECIFE | E16: 2611606 | F16: INTELICOM | H16: Av. Abdias de Carvalho - Madalena | I16: PAINEL ELETRÔNICO | J16: MENSAL PROPORCIONAL | K16: VIAS DE ALTO FLUXO | L16: 10" | M16: 46219 | N16: =M16+O16-1 -> 46220 | O16: 2 | P16: 1 | Q16: 510 | R16: =Q16*P16*O16 -> 1020 | S16: 1 | T16: =31913*0.7/7*O16 -> 6382.6 | U16: =T16 -> 6382.6 | V16: 0 | W16: =T16-T16*V16 -> 6382.6 | X16: =U16*(1-V16) -> 6382.6 | Y16: =X16*0.95 -> 6063.47 | Z16: =Z14 -> 70000 | AA16: =R16 -> 1020 | AB16: =X16/(AA16+AA24) -> 1.135694 | AC16: =X16/(AA16+AA24)*1000 -> 1135.694 | AD16: DIRETO
B17: 82219 | C17: PE | D17: RECIFE | E17: 2611606 | F17: INTELICOM | H17: Av. Conselheiro Rosa e Silva - Tamarineira | I17: PAINEL ELETRÔNICO | J17: MENSAL PROPORCIONAL | K17: VIAS DE ALTO FLUXO | L17: 10" | M17: 46219 | N17: =M17+O17-1 -> 46220 | O17: 2 | P17: 1 | Q17: 510 | R17: =Q17*P17*O17 -> 1020 | S17: 1 | T17: =31913*0.7/7*O17 -> 6382.6 | U17: =T17 -> 6382.6 | V17: 0 | W17: =T17-T17*V17 -> 6382.6 | X17: =U17*(1-V17) -> 6382.6 | Y17: =X17*0.95 -> 6063.47 | Z17: 70000 | AA17: =R17 -> 1020 | AB17: =X17/(AA17+AA19) -> 3.1287255 | AC17: =X17/(AA17+AA19)*1000 -> 3128.7255 | AD17: DIRETO
B18: 82219 | C18: PE | D18: RECIFE | E18: 2611606 | F18: INTELICOM | H18: Av. 17 de Agosto - Casa Forte | I18: PAINEL ELETRÔNICO | J18: MENSAL PROPORCIONAL | K18: VIAS DE ALTO FLUXO | L18: 10" | M18: 46219 | N18: =M18+O18-1 -> 46220 | O18: 2 | P18: 1 | Q18: 510 | R18: =Q18*P18*O18 -> 1020 | S18: 1 | T18: =31913*0.7/7*O18 -> 6382.6 | U18: =T18 -> 6382.6 | V18: 0 | W18: =T18-T18*V18 -> 6382.6 | X18: =U18*(1-V18) -> 6382.6 | Y18: =X18*0.95 -> 6063.47 | Z18: 70000 | AA18: =R18 -> 1020 | AB18: =X18/(AA18+AA26) -> 6.257451 | AC18: =X18/(AA18+AA26)*1000 -> 6257.451 | AD18: DIRETO
B19: 82219 | C19: PE | D19: RECIFE | E19: 2611606 | F19: INTELICOM | H19: Av. Conselheiro Aguiar - Avenida | I19: PAINEL ELETRÔNICO | J19: MENSAL PROPORCIONAL | K19: VIAS DE ALTO FLUXO | L19: 10" | M19: 46219 | N19: =M19+O19-1 -> 46220 | O19: 2 | P19: 1 | Q19: 510 | R19: =Q19*P19*O19 -> 1020 | S19: 1 | T19: =31913*0.7/7*O19 -> 6382.6 | U19: =T19 -> 6382.6 | V19: 0 | W19: =T19-T19*V19 -> 6382.6 | X19: =U19*(1-V19) -> 6382.6 | Y19: =X19*0.95 -> 6063.47 | Z19: =Z17 -> 70000 | AA19: =R19 -> 1020 | AB19: =X19/(AA19+AA27) -> 1.8662573 | AC19: =X19/(AA19+AA27)*1000 -> 1866.2573 | AD19: DIRETO
B20: 82219 | C20: PE | D20: RECIFE | E20: 2611606 | F20: INTELICOM | H20: Av. Engenheiro Domingos - Avenida | I20: PAINEL ELETRÔNICO | J20: MENSAL PROPORCIONAL | K20: VIAS DE ALTO FLUXO | L20: 10" | M20: 46219 | N20: =M20+O20-1 -> 46220 | O20: 2 | P20: 1 | Q20: 510 | R20: =Q20*P20*O20 -> 1020 | S20: 1 | T20: =31913*0.7/7*O20 -> 6382.6 | U20: =T20 -> 6382.6 | V20: 0 | W20: =T20-T20*V20 -> 6382.6 | X20: =U20*(1-V20) -> 6382.6 | Y20: =X20*0.95 -> 6063.47 | Z20: 70000 | AA20: =R20 -> 1020 | AB20: =X20/(AA20+AA22) -> 3.1287255 | AC20: =X20/(AA20+AA22)*1000 -> 3128.7255 | AD20: DIRETO
B21: 82219 | C21: PE | D21: RECIFE | E21: 2611606 | F21: INTELICOM | H21: Av. Gov. Agamenon - Ilha do \leite | I21: PAINEL ELETRÔNICO | J21: MENSAL PROPORCIONAL | K21: VIAS DE ALTO FLUXO | L21: 10" | M21: 46219 | N21: =M21+O21-1 -> 46220 | O21: 2 | P21: 1 | Q21: 510 | R21: =Q21*P21*O21 -> 1020 | S21: 1 | T21: =31913*0.7/7*O21 -> 6382.6 | U21: =T21 -> 6382.6 | V21: 0 | W21: =T21-T21*V21 -> 6382.6 | X21: =U21*(1-V21) -> 6382.6 | Y21: =X21*0.95 -> 6063.47 | Z21: 70000 | AA21: =R21 -> 1020 | AB21: =X21/(AA21+AA29) -> 2.5945528 | AC21: =X21/(AA21+AA29)*1000 -> 2594.5528 | AD21: DIRETO
B22: 82219 | C22: PE | D22: RECIFE | E22: 2611606 | F22: INTELICOM | H22: Av. Eng. Abdias de Carvalho - Avenida | I22: PAINEL ELETRÔNICO | J22: MENSAL PROPORCIONAL | K22: VIAS DE ALTO FLUXO | L22: 10" | M22: 46219 | N22: =M22+O22-1 -> 46220 | O22: 2 | P22: 1 | Q22: 510 | R22: =Q22*P22*O22 -> 1020 | S22: 1 | T22: =31913*0.7/7*O22 -> 6382.6 | U22: =T22 -> 6382.6 | V22: 0 | W22: =T22-T22*V22 -> 6382.6 | X22: =U22*(1-V22) -> 6382.6 | Y22: =X22*0.95 -> 6063.47 | Z22: =Z20 -> 70000 | AA22: =R22 -> 1020 | AB22: =X22/(AA22+AA30) -> 6.257451 | AC22: =X22/(AA22+AA30)*1000 -> 6257.451 | AD22: DIRETO
B23: 107541 | C23: PE | D23: RECIFE | E23: 2611606 | F23: MLA MIDIA | G23: 52.008.394/0001-28 | H23: ERNESTO PAULA SANTOS Nº 867 - RECIFE | I23: PAINEL ELETRÔNICO | J23: MENSAL PROPORCIONAL | K23: VIAS DE ALTO FLUXO | L23: 10" | M23: 46219 | N23: =M23+O23-1 -> 46220 | O23: 2 | P23: 1 | Q23: 2300 | R23: =Q23*P23*O23 -> 4600 | S23: 1 | T23: 5.4 | U23: =T23*R23 -> 24840 | V23: 0.66 | W23: =T23-T23*V23 -> 1.836 | X23: =U23*(1-V23) -> 8445.6 | Y23: =X23*0.95 -> 8023.32 | Z23: 70000 | AA23: =R23 -> 4600 | AB23: =X23/(AA23+AA25) -> 0.918 | AC23: =X23/(AA23+AA25)*1000 -> 918 | AD23: DIRETO
B24: 107541 | C24: PE | D24: RECIFE | E24: 2611606 | F24: MLA MIDIA | G24: 52.008.394/0001-28 | H24: AV. GOV. AGAMENON MAGALHÃES Nº2656 - RECIFE | I24: PAINEL ELETRÔNICO | J24: MENSAL PROPORCIONAL | K24: VIAS DE ALTO FLUXO | L24: 10" | M24: 46219 | N24: =M24+O24-1 -> 46220 | O24: 2 | P24: 1 | Q24: 2300 | R24: =Q24*P24*O24 -> 4600 | S24: 1 | T24: 5.4 | U24: =T24*R24 -> 24840 | V24: 0.66 | W24: =T24-T24*V24 -> 1.836 | X24: =U24*(1-V24) -> 8445.6 | Y24: =X24*0.95 -> 8023.32 | Z24: 70000 | AA24: =R24 -> 4600 | AB24: =X24/(AA24+AA26) -> 1.836 | AC24: =X24/(AA24+AA26)*1000 -> 1836 | AD24: DIRETO
B25: 107541 | C25: PE | D25: RECIFE | E25: 2611606 | F25: MLA MIDIA | G25: 52.008.394/0001-28 | H25: AV. DOMINGOS FERREIRA Nº1537 - RECIFE | I25: PAINEL ELETRÔNICO | J25: MENSAL PROPORCIONAL | K25: VIAS DE ALTO FLUXO | L25: 10" | M25: 46219 | N25: =M25+O25-1 -> 46220 | O25: 2 | P25: 1 | Q25: 2300 | R25: =Q25*P25*O25 -> 4600 | S25: 1 | T25: 5.4 | U25: =T25*R25 -> 24840 | V25: 0.66 | W25: =T25-T25*V25 -> 1.836 | X25: =U25*(1-V25) -> 8445.6 | Y25: =X25*0.95 -> 8023.32 | Z25: =Z23 -> 70000 | AA25: =R25 -> 4600 | AB25: =X25/(AA25+AA27) -> 1.2065143 | AC25: =X25/(AA25+AA27)*1000 -> 1206.5143 | AD25: DIRETO
B26: TOTAL - PERNAMBUCO | P26: =SUBTOTAL(9,P11:P25) -> 15 | R26: =SUBTOTAL(9,R11:R25) -> 29040 | X26: =SUBTOTAL(9,X11:X25) -> 94329.686 | Y26: =SUBTOTAL(9,Y11:Y25) -> 89613.202 | AC26: =AVERAGE(AC11:AC25)*1.5 -> 4040.2111
B27: 87254 | C27: PR | D27: CURITIBA | E27: 4106902 | F27: LED MAIS | G27: 28.507.808/0001-89 | H27: AV. IGUAÇU 4399, ESQ. COM RUA ARTHUR BERNARDES - TERRENO DA SOUQ | I27: PAINEL ELETRÔNICO | J27: POR INSERÇÃO | K27: VIAS DE ALTO FLUXO | L27: 10" | M27: 46219 | N27: =M27+O27-1 -> 46220 | O27: 2 | P27: 1 | Q27: 1200 | R27: =Q27*P27*O27 -> 2400 | S27: 1 | T27: 4.65 | U27: =T27*R27 -> 11160 | V27: 0.25 | W27: =T27-T27*V27 -> 3.4875 | X27: =U27*(1-V27) -> 8370 | Y27: =X27*0.95 -> 7951.5 | Z27: - | AA27: =R27 -> 2400 | AB27: - | AC27: - | AD27: G2
B28: 87254 | C28: PR | D28: CURITIBA | E28: 4106902 | F28: LED MAIS | G28: 28.507.808/0001-89 | H28: RODOVIA JOÃO LEOPOLDO JACOMEL 12627 RETENÇÃO DE SINALEIRO - ESQ. COM AV. MARINGÁ SENT. PINHAIS | I28: PAINEL ELETRÔNICO | J28: POR INSERÇÃO | K28: VIAS DE ALTO FLUXO | L28: 10" | M28: 46219 | N28: =M28+O28-1 -> 46220 | O28: 2 | P28: 1 | Q28: 1200 | R28: =Q28*P28*O28 -> 2400 | S28: 1 | T28: 4.65 | U28: =T28*R28 -> 11160 | V28: 0.25 | W28: =T28-T28*V28 -> 3.4875 | X28: =U28*(1-V28) -> 8370 | Y28: =X28*0.95 -> 7951.5 | Z28: - | AA28: =R28 -> 2400 | AB28: - | AC28: - | AD28: G2
B29: 67263 | C29: PR | D29: CURITIBA | E29: 4106902 | F29: PLAN PAINÉIS | G29: 13.517.365/0001-30 | H29: RUA MAUA, 452, ANEXO AO ESTADIO MAJOR ANTONIO COUTO PEREIRA | I29: PAINEL ELETRÔNICO | J29: PERÍODO | K29: VIAS DE ALTO FLUXO | L29: 10" | M29: 46219 | N29: =M29+O29-1 -> 46220 | O29: 2 | P29: 1 | Q29: =360*2 -> 720 | R29: =Q29*P29*O29 -> 1440 | S29: 1 | T29: =7375/7*O29 -> 2107.1429 | U29: =T29*S29 -> 2107.1429 | V29: 0.1 | W29: =T29-T29*V29 -> 1896.4286 | X29: =U29*(1-V29) -> 1896.4286 | Y29: =X29*0.95 -> 1801.6071 | Z29: - | AA29: =R29 -> 1440 | AB29: - | AC29: - | AD29: DIRETO
B30: TOTAL - PARANÁ | P30: =SUBTOTAL(9,P27:P29) -> 3 | R30: =SUBTOTAL(9,R27:R29) -> 6240 | X30: =SUBTOTAL(9,X27:X29) -> 18636.429 | Y30: =SUBTOTAL(9,Y27:Y29) -> 17704.607 | AC30: =AVERAGE(AC27:AC29)*1.5 -> #DIV/0!
B31: 87254 | C31: BA | D31: SALVADOR | E31: 2927408 | F31: LED MAIS | G31: 28.507.808/0001-89 | H31: AV. SANTOS DUMONT (PROXIMO AO ASSAI ATACADISTA) | I31: PAINEL ELETRÔNICO | J31: MENSAL PROPORCIONAL | K31: VIAS DE ALTO FLUXO | L31: 10" | M31: 46219 | N31: =M31+O31-1 -> 46220 | O31: 2 | P31: 1 | Q31: 1200 | R31: =Q31*P31*O31 -> 2400 | S31: 1 | T31: 4.65 | U31: =T31*R31 -> 11160 | V31: 0.25 | W31: =T31-T31*V31 -> 3.4875 | X31: =U31*(1-V31) -> 8370 | Y31: =X31*0.95 -> 7951.5 | Z31: - | AA31: =R31 -> 2400 | AB31: - | AC31: - | AD31: G2
B32: 87254 | C32: BA | D32: SALVADOR | E32: 2927408 | F32: LED MAIS | G32: 28.507.808/0001-89 | H32: AV. PRINCESA ISABEL (PROXIMO A PIZZA HUT) | I32: PAINEL ELETRÔNICO | J32: MENSAL PROPORCIONAL | K32: VIAS DE ALTO FLUXO | L32: 10" | M32: 46219 | N32: =M32+O32-1 -> 46220 | O32: 2 | P32: 1 | Q32: 1200 | R32: =Q32*P32*O32 -> 2400 | S32: 1 | T32: 4.65 | U32: =T32*R32 -> 11160 | V32: 0.25 | W32: =T32-T32*V32 -> 3.4875 | X32: =U32*(1-V32) -> 8370 | Y32: =X32*0.95 -> 7951.5 | Z32: - | AA32: =R32 -> 2400 | AB32: - | AC32: - | AD32: G2
B33: TOTAL - BAHIA | P33: =SUBTOTAL(9,P31:P32) -> 2 | R33: =SUBTOTAL(9,R31:R32) -> 4800 | X33: =SUBTOTAL(9,X31:X32) -> 16740 | Y33: =SUBTOTAL(9,Y31:Y32) -> 15903 | AC33: =AVERAGE(AC31:AC32)*1.5 -> #DIV/0!
B34: 84398 | C34: CE | D34: FORTALEZA | E34: 2304400 | F34: 55 MÍDIA | G34: 42.317.692/0001-46 | H34: AV BARÃO DE STUDART, 81- MEIRELES | I34: MEGA PAINEL DE LED 3D | J34: POR INSERÇÃO | K34: VIAS DE ALTO FLUXO | L34: 15" | M34: 46219 | N34: =M34+O34-1 -> 46220 | O34: 2 | P34: 1 | Q34: 1500 | R34: =Q34*P34*O34 -> 3000 | S34: 1 | T34: 15.69 | U34: =T34*R34 -> 47070 | V34: 0.21 | W34: =T34-T34*V34 -> 12.3951 | X34: =U34*(1-V34) -> 37185.3 | Y34: =X34*0.95 -> 35326.035 | Z34: 63535.857 | AA34: 444751 | AB34: =X34/(AA34+AA35) -> 0.052108204 | AC34: =X34/(AA34+AA35)*1000 -> 52.108204 | AD34: MIDIA MAIS
B35: 84398 | C35: CE | D35: FORTALEZA | E35: 2304400 | F35: 55 MÍDIA | G35: 42.317.692/0001-46 | H35: AV JULIO ABREU, 291, MEIRELES | I35: PAINEL DE LED | J35: POR INSERÇÃO | K35: VIAS DE ALTO FLUXO | L35: 15" | M35: 46219 | N35: =M35+O35-1 -> 46220 | O35: 2 | P35: 1 | Q35: 1500 | R35: =Q35*P35*O35 -> 3000 | S35: 1 | T35: 3.66 | U35: =T35*R35 -> 10980 | V35: 0.21 | W35: =T35-T35*V35 -> 2.8914 | X35: =U35*(1-V35) -> 8674.2 | Y35: =X35*0.95 -> 8240.49 | Z35: 38409 | AA35: 268866 | AB35: =X35/(AA35+AA36) -> 0.020079167 | AC35: =X35/(AA35+AA36)*1000 -> 20.079167 | AD35: MIDIA MAIS
B36: 84398 | C36: CE | D36: FORTALEZA | E36: 2304400 | F36: 55 MÍDIA | G36: 42.317.692/0001-46 | H36: RUA ILDEFONSO ALBANO, 2260 - ALDEOTA | I36: PAINEL DE LED | J36: POR INSERÇÃO | K36: VIAS DE ALTO FLUXO | L36: 15" | M36: 46219 | N36: =M36+O36-1 -> 46220 | O36: 2 | P36: 1 | Q36: 1500 | R36: =Q36*P36*O36 -> 3000 | S36: 1 | T36: 3.66 | U36: =T36*R36 -> 10980 | V36: 0.21 | W36: =T36-T36*V36 -> 2.8914 | X36: =U36*(1-V36) -> 8674.2 | Y36: =X36*0.95 -> 8240.49 | Z36: 23305 | AA36: 163134 | AB36: =X36/(AA36+AA37) -> 0.027369451 | AC36: =X36/(AA36+AA37)*1000 -> 27.369451 | AD36: MIDIA MAIS
B37: 84398 | C37: CE | D37: FORTALEZA | E37: 2304400 | F37: 55 MÍDIA | G37: 42.317.692/0001-46 | H37: AV BARÃO DE STUDART, 100 - MEIRELES | I37: PAINEL DE LED | J37: POR INSERÇÃO | K37: VIAS DE ALTO FLUXO | L37: 15" | M37: 46219 | N37: =M37+O37-1 -> 46220 | O37: 2 | P37: 1 | Q37: 1500 | R37: =Q37*P37*O37 -> 3000 | S37: 1 | T37: 3.66 | U37: =T37*R37 -> 10980 | V37: 0.21 | W37: =T37-T37*V37 -> 2.8914 | X37: =U37*(1-V37) -> 8674.2 | Y37: =X37*0.95 -> 8240.49 | Z37: 21971 | AA37: 153796 | AB37: =X37/(AA37+AA38) -> 0.024196828 | AC37: =X37/(AA37+AA38)*1000 -> 24.196828 | AD37: MIDIA MAIS
